<sdf version='1.6'>
  <world name='default'>
    <light name='sun' type='directional'>
      <cast_shadows>1</cast_shadows>
      <pose frame=''>0 0 10 0 -0 0</pose>
      <diffuse>0.8 0.8 0.8 1</diffuse>
      <specular>0.2 0.2 0.2 1</specular>
      <attenuation>
        <range>1000</range>
        <constant>0.9</constant>
        <linear>0.01</linear>
        <quadratic>0.001</quadratic>
      </attenuation>
      <direction>-0.5 0.1 -0.9</direction>
    </light>
    <model name='ground_plane'>
      <static>1</static>
      <link name='link'>
        <collision name='collision'>
          <geometry>
            <plane>
              <normal>0 0 1</normal>
              <size>100 100</size>
            </plane>
          </geometry>
          <surface>
            <contact>
              <collide_bitmask>65535</collide_bitmask>
              <ode/>
            </contact>
            <friction>
              <ode>
                <mu>100</mu>
                <mu2>50</mu2>
              </ode>
              <torsional>
                <ode/>
              </torsional>
            </friction>
            <bounce/>
          </surface>
          <max_contacts>10</max_contacts>
        </collision>
        <visual name='visual'>
          <cast_shadows>0</cast_shadows>
          <geometry>
            <plane>
              <normal>0 0 1</normal>
              <size>100 100</size>
            </plane>
          </geometry>
          <material>
            <script>
              <uri>file://media/materials/scripts/gazebo.material</uri>
              <name>Gazebo/Grey</name>
            </script>
          </material>
        </visual>
        <self_collide>0</self_collide>
        <enable_wind>0</enable_wind>
        <kinematic>0</kinematic>
      </link>
    </model>
    <gravity>0 0 -9.8</gravity>
    <magnetic_field>6e-06 2.3e-05 -4.2e-05</magnetic_field>
    <atmosphere type='adiabatic'/>
    <physics name='default_physics' default='0' type='ode'>
      <max_step_size>0.001</max_step_size>
      <real_time_factor>1</real_time_factor>
      <real_time_update_rate>1000</real_time_update_rate>
    </physics>
    <scene>
      <ambient>0.4 0.4 0.4 1</ambient>
      <background>0.7 0.7 0.7 1</background>
      <shadows>1</shadows>
    </scene>
    <audio>
      <device>default</device>
    </audio>
    <wind/>
    <spherical_coordinates>
      <surface_model>EARTH_WGS84</surface_model>
      <latitude_deg>0</latitude_deg>
      <longitude_deg>0</longitude_deg>
      <elevation>0</elevation>
      <heading_deg>0</heading_deg>
    </spherical_coordinates>
    <model name='my_spideybot'>
      <link name='dummy'>
        <pose frame=''>0 0 0 0 -0 0</pose>
        <inertial>
          <pose frame=''>0.086929 -0.18825 0.11918 0 -0 0</pose>
          <mass>0.53458</mass>
          <inertia>
            <ixx>0.0020324</ixx>
            <ixy>0</ixy>
            <ixz>0</ixz>
            <iyy>0.0015098</iyy>
            <iyz>0</iyz>
            <izz>0.0035077</izz>
          </inertia>
        </inertial>
        <collision name='dummy_fixed_joint_lump__base_link_collision'>
          <pose frame=''>0 0 0 0 -0 0</pose>
          <geometry>
            <mesh>
              <scale>1 1 1</scale>
              <uri>/home/chhinkein/zeeskee_ws/src/my_spideybot/meshes/base_link.STL</uri>
            </mesh>
          </geometry>
          <surface>
            <contact>
              <ode/>
            </contact>
            <friction>
              <ode/>
              <torsional>
                <ode/>
              </torsional>
            </friction>
            <bounce/>
          </surface>
          <max_contacts>10</max_contacts>
        </collision>
        <visual name='dummy_fixed_joint_lump__base_link_visual'>
          <pose frame=''>0 0 0 0 -0 0</pose>
          <geometry>
            <mesh>
              <scale>1 1 1</scale>
              <uri>/home/chhinkein/zeeskee_ws/src/my_spideybot/meshes/base_link.STL</uri>
            </mesh>
          </geometry>
          <material>
            <script>
              <name>Gazebo/Red</name>
              <uri>file://media/materials/scripts/gazebo.material</uri>
            </script>
          </material>
        </visual>
        <visual name='dummy_fixed_joint_lump__camera_link_visual_1'>
          <pose frame=''>0.086929 -0.095 0.136 0 -0 1.52</pose>
          <geometry>
            <box>
              <size>0.02 0.02 0.02</size>
            </box>
          </geometry>
          <material>
            <script>
              <name>Gazebo/Green</name>
              <uri>file://media/materials/scripts/gazebo.material</uri>
            </script>
          </material>
        </visual>
        <velocity_decay/>
        <velocity_decay/>
        <sensor name='camera1' type='camera'>
          <update_rate>30</update_rate>
          <camera name='head'>
            <horizontal_fov>1.39626</horizontal_fov>
            <image>
              <width>800</width>
              <height>800</height>
              <format>R8G8B8</format>
            </image>
            <clip>
              <near>0.02</near>
              <far>300</far>
            </clip>
          </camera>
          <plugin name='camera_controller' filename='libgazebo_ros_camera.so'>
            <alwaysOn>1</alwaysOn>
            <updateRate>0.0</updateRate>
            <cameraName>my_spideybot/camera1</cameraName>
            <imageTopicName>image_raw</imageTopicName>
            <cameraInfoTopicName>camera_info</cameraInfoTopicName>
            <frameName>camera_link</frameName>
            <hackBaseline>0.07</hackBaseline>
            <distortionK1>0.0</distortionK1>
            <distortionK2>0.0</distortionK2>
            <distortionK3>0.0</distortionK3>
            <distortionT1>0.0</distortionT1>
            <distortionT2>0.0</distortionT2>
            <robotNamespace>/</robotNamespace>
          </plugin>
          <pose frame=''>0.086929 -0.095 0.136 0 -0 1.52</pose>
        </sensor>
        <gravity>1</gravity>
        <velocity_decay/>
        <self_collide>0</self_collide>
        <enable_wind>0</enable_wind>
        <kinematic>0</kinematic>
      </link>
      <link name='hip1_link'>
        <pose frame=''>0.011929 -0.28825 0.10168 1.5708 0 -0.6435</pose>
        <inertial>
          <pose frame=''>0 0.0175 0.02875 0 -0 0</pose>
          <mass>0.010462</mass>
          <inertia>
            <ixx>1.9878e-06</ixx>
            <ixy>-1.2808e-23</ixy>
            <ixz>-2.1176e-22</ixz>
            <iyy>1.9878e-06</iyy>
            <iyz>-4.8885e-13</iyz>
            <izz>6.7997e-07</izz>
          </inertia>
        </inertial>
        <collision name='hip1_link_collision'>
          <pose frame=''>0 0 0 0 -0 0</pose>
          <geometry>
            <mesh>
              <scale>1 1 1</scale>
              <uri>/home/chhinkein/zeeskee_ws/src/my_spideybot/meshes/hip1_link.STL</uri>
            </mesh>
          </geometry>
          <surface>
            <contact>
              <ode/>
            </contact>
            <friction>
              <ode/>
              <torsional>
                <ode/>
              </torsional>
            </friction>
            <bounce/>
          </surface>
          <max_contacts>10</max_contacts>
        </collision>
        <visual name='hip1_link_visual'>
          <pose frame=''>0 0 0 0 -0 0</pose>
          <geometry>
            <mesh>
              <scale>1 1 1</scale>
              <uri>/home/chhinkein/zeeskee_ws/src/my_spideybot/meshes/hip1_link.STL</uri>
            </mesh>
          </geometry>
          <material>
            <script>
              <name>Gazebo/Blue</name>
              <uri>file://media/materials/scripts/gazebo.material</uri>
            </script>
          </material>
        </visual>
        <gravity>1</gravity>
        <velocity_decay/>
        <self_collide>0</self_collide>
        <enable_wind>0</enable_wind>
        <kinematic>0</kinematic>
      </link>
      <joint name='hip1_joint' type='revolute'>
        <child>hip1_link</child>
        <parent>dummy</parent>
        <axis>
          <xyz>-2e-06 -3e-06 1</xyz>
          <limit>
            <lower>-2.09</lower>
            <upper>2.09</upper>
            <effort>20</effort>
            <velocity>5</velocity>
          </limit>
          <dynamics>
            <spring_reference>0</spring_reference>
            <spring_stiffness>0</spring_stiffness>
          </dynamics>
          <use_parent_model_frame>1</use_parent_model_frame>
        </axis>
      </joint>
      <link name='thigh1_link'>
        <pose frame=''>-0.022571 -0.33425 0.11918 -2.35619 -1.57079 -2.99969</pose>
        <inertial>
          <pose frame=''>0 -2e-06 0.018733 0 -0 0</pose>
          <mass>0.027144</mass>
          <inertia>
            <ixx>7.8675e-06</ixx>
            <ixy>-1.8487e-17</ixy>
            <ixz>-1.8122e-17</ixz>
            <iyy>6.523e-06</iyy>
            <iyz>-3.5464e-10</iyz>
            <izz>2.8446e-06</izz>
          </inertia>
        </inertial>
        <collision name='thigh1_link_collision'>
          <pose frame=''>0 0 0 0 -0 0</pose>
          <geometry>
            <mesh>
              <scale>1 1 1</scale>
              <uri>/home/chhinkein/zeeskee_ws/src/my_spideybot/meshes/thigh1_link.STL</uri>
            </mesh>
          </geometry>
          <surface>
            <contact>
              <ode/>
            </contact>
            <friction>
              <ode/>
              <torsional>
                <ode/>
              </torsional>
            </friction>
            <bounce/>
          </surface>
          <max_contacts>10</max_contacts>
        </collision>
        <visual name='thigh1_link_visual'>
          <pose frame=''>0 0 0 0 -0 0</pose>
          <geometry>
            <mesh>
              <scale>1 1 1</scale>
              <uri>/home/chhinkein/zeeskee_ws/src/my_spideybot/meshes/thigh1_link.STL</uri>
            </mesh>
          </geometry>
          <material>
            <script>
              <name>Gazebo/Orange</name>
              <uri>file://media/materials/scripts/gazebo.material</uri>
            </script>
          </material>
        </visual>
        <gravity>1</gravity>
        <velocity_decay/>
        <self_collide>0</self_collide>
        <enable_wind>0</enable_wind>
        <kinematic>0</kinematic>
      </link>
      <joint name='thigh1_joint' type='revolute'>
        <child>thigh1_link</child>
        <parent>hip1_link</parent>
        <axis>
          <xyz>0.800001 -0.599999 4e-06</xyz>
          <limit>
            <lower>-2.09</lower>
            <upper>2.09</upper>
            <effort>20</effort>
            <velocity>5</velocity>
          </limit>
          <dynamics>
            <spring_reference>0</spring_reference>
            <spring_stiffness>0</spring_stiffness>
          </dynamics>
          <use_parent_model_frame>1</use_parent_model_frame>
        </axis>
      </joint>
      <link name='leg1_link'>
        <pose frame=''>-0.070571 -0.39825 0.119179 -3.14159 0 -0.6435</pose>
        <inertial>
          <pose frame=''>2.7e-05 -0 0.022876 0 -0 0</pose>
          <mass>0.028117</mass>
          <inertia>
            <ixx>2.0146e-05</ixx>
            <ixy>8.4703e-22</ixy>
            <ixz>-4.0889e-08</ixz>
            <iyy>2.1225e-05</iyy>
            <iyz>2.2443e-22</iyz>
            <izz>2.6051e-06</izz>
          </inertia>
        </inertial>
        <collision name='leg1_link_collision'>
          <pose frame=''>0 0 0 0 -0 0</pose>
          <geometry>
            <mesh>
              <scale>1 1 1</scale>
              <uri>/home/chhinkein/zeeskee_ws/src/my_spideybot/meshes/leg1_link.STL</uri>
            </mesh>
          </geometry>
          <surface>
            <contact>
              <ode/>
            </contact>
            <friction>
              <ode/>
              <torsional>
                <ode/>
              </torsional>
            </friction>
            <bounce/>
          </surface>
          <max_contacts>10</max_contacts>
        </collision>
        <visual name='leg1_link_visual'>
          <pose frame=''>0 0 0 0 -0 0</pose>
          <geometry>
            <mesh>
              <scale>1 1 1</scale>
              <uri>/home/chhinkein/zeeskee_ws/src/my_spideybot/meshes/leg1_link.STL</uri>
            </mesh>
          </geometry>
          <material>
            <script>
              <name>Gazebo/Orange</name>
              <uri>file://media/materials/scripts/gazebo.material</uri>
            </script>
          </material>
        </visual>
        <gravity>1</gravity>
        <velocity_decay/>
        <self_collide>0</self_collide>
        <enable_wind>0</enable_wind>
        <kinematic>0</kinematic>
      </link>
      <joint name='leg1_joint' type='revolute'>
        <child>leg1_link</child>
        <parent>thigh1_link</parent>
        <axis>
          <xyz>0.800001 -0.599999 -0</xyz>
          <limit>
            <lower>-2.09</lower>
            <upper>2.09</upper>
            <effort>20</effort>
            <velocity>5</velocity>
          </limit>
          <dynamics>
            <spring_reference>0</spring_reference>
            <spring_stiffness>0</spring_stiffness>
          </dynamics>
          <use_parent_model_frame>1</use_parent_model_frame>
        </axis>
      </joint>
      <link name='hip2_link'>
        <pose frame=''>-0.018071 -0.18825 0.10168 -1.5708 -0 -1.5708</pose>
        <inertial>
          <pose frame=''>0 -0.0175 -0.02875 0 -0 0</pose>
          <mass>0.010462</mass>
          <inertia>
            <ixx>1.9878e-06</ixx>
            <ixy>2.0602e-24</ixy>
            <ixz>7.0783e-23</ixz>
            <iyy>1.9878e-06</iyy>
            <iyz>-4.8885e-13</iyz>
            <izz>6.7997e-07</izz>
          </inertia>
        </inertial>
        <collision name='hip2_link_collision'>
          <pose frame=''>0 0 0 0 -0 0</pose>
          <geometry>
            <mesh>
              <scale>1 1 1</scale>
              <uri>/home/chhinkein/zeeskee_ws/src/my_spideybot/meshes/hip2_link.STL</uri>
            </mesh>
          </geometry>
          <surface>
            <contact>
              <ode/>
            </contact>
            <friction>
              <ode/>
              <torsional>
                <ode/>
              </torsional>
            </friction>
            <bounce/>
          </surface>
          <max_contacts>10</max_contacts>
        </collision>
        <visual name='hip2_link_visual'>
          <pose frame=''>0 0 0 0 -0 0</pose>
          <geometry>
            <mesh>
              <scale>1 1 1</scale>
              <uri>/home/chhinkein/zeeskee_ws/src/my_spideybot/meshes/hip2_link.STL</uri>
            </mesh>
          </geometry>
          <material>
            <script>
              <name>Gazebo/Blue</name>
              <uri>file://media/materials/scripts/gazebo.material</uri>
            </script>
          </material>
        </visual>
        <gravity>1</gravity>
        <velocity_decay/>
        <self_collide>0</self_collide>
        <enable_wind>0</enable_wind>
        <kinematic>0</kinematic>
      </link>
      <joint name='hip2_joint' type='revolute'>
        <child>hip2_link</child>
        <parent>dummy</parent>
        <axis>
          <xyz>4e-06 -0 1</xyz>
          <limit>
            <lower>-2.09</lower>
            <upper>2.09</upper>
            <effort>20</effort>
            <velocity>5</velocity>
          </limit>
          <dynamics>
            <spring_reference>0</spring_reference>
            <spring_stiffness>0</spring_stiffness>
          </dynamics>
          <use_parent_model_frame>1</use_parent_model_frame>
        </axis>
      </joint>
      <link name='thigh2_link'>
        <pose frame=''>-0.075571 -0.18825 0.11918 -0.785391 -1.57079 0.785394</pose>
        <inertial>
          <pose frame=''>0 -2e-06 0.018733 0 -0 0</pose>
          <mass>0.027144</mass>
          <inertia>
            <ixx>7.8675e-06</ixx>
            <ixy>-2.1304e-17</ixy>
            <ixz>1.0487e-17</ixz>
            <iyy>6.523e-06</iyy>
            <iyz>-3.5464e-10</iyz>
            <izz>2.8446e-06</izz>
          </inertia>
        </inertial>
        <collision name='thigh2_link_collision'>
          <pose frame=''>0 0 0 0 -0 0</pose>
          <geometry>
            <mesh>
              <scale>1 1 1</scale>
              <uri>/home/chhinkein/zeeskee_ws/src/my_spideybot/meshes/thigh2_link.STL</uri>
            </mesh>
          </geometry>
          <surface>
            <contact>
              <ode/>
            </contact>
            <friction>
              <ode/>
              <torsional>
                <ode/>
              </torsional>
            </friction>
            <bounce/>
          </surface>
          <max_contacts>10</max_contacts>
        </collision>
        <visual name='thigh2_link_visual'>
          <pose frame=''>0 0 0 0 -0 0</pose>
          <geometry>
            <mesh>
              <scale>1 1 1</scale>
              <uri>/home/chhinkein/zeeskee_ws/src/my_spideybot/meshes/thigh2_link.STL</uri>
            </mesh>
          </geometry>
          <material>
            <script>
              <name>Gazebo/Orange</name>
              <uri>file://media/materials/scripts/gazebo.material</uri>
            </script>
          </material>
        </visual>
        <gravity>1</gravity>
        <velocity_decay/>
        <self_collide>0</self_collide>
        <enable_wind>0</enable_wind>
        <kinematic>0</kinematic>
      </link>
      <joint name='thigh2_joint' type='revolute'>
        <child>thigh2_link</child>
        <parent>hip2_link</parent>
        <axis>
          <xyz>-4e-06 1 -4e-06</xyz>
          <limit>
            <lower>-2.09</lower>
            <upper>2.09</upper>
            <effort>20</effort>
            <velocity>5</velocity>
          </limit>
          <dynamics>
            <spring_reference>0</spring_reference>
            <spring_stiffness>0</spring_stiffness>
          </dynamics>
          <use_parent_model_frame>1</use_parent_model_frame>
        </axis>
      </joint>
      <link name='leg2_link'>
        <pose frame=''>-0.155571 -0.18825 0.119181 3.14159 -0 -1.57079</pose>
        <inertial>
          <pose frame=''>2.7e-05 0 0.022876 0 -0 0</pose>
          <mass>0.028117</mass>
          <inertia>
            <ixx>2.0146e-05</ixx>
            <ixy>-1.5748e-14</ixy>
            <ixz>-4.0889e-08</ixz>
            <iyy>2.1225e-05</iyy>
            <iyz>-5.9677e-16</iyz>
            <izz>2.6051e-06</izz>
          </inertia>
        </inertial>
        <collision name='leg2_link_collision'>
          <pose frame=''>0 0 0 0 -0 0</pose>
          <geometry>
            <mesh>
              <scale>1 1 1</scale>
              <uri>/home/chhinkein/zeeskee_ws/src/my_spideybot/meshes/leg2_link.STL</uri>
            </mesh>
          </geometry>
          <surface>
            <contact>
              <ode/>
            </contact>
            <friction>
              <ode/>
              <torsional>
                <ode/>
              </torsional>
            </friction>
            <bounce/>
          </surface>
          <max_contacts>10</max_contacts>
        </collision>
        <visual name='leg2_link_visual'>
          <pose frame=''>0 0 0 0 -0 0</pose>
          <geometry>
            <mesh>
              <scale>1 1 1</scale>
              <uri>/home/chhinkein/zeeskee_ws/src/my_spideybot/meshes/leg2_link.STL</uri>
            </mesh>
          </geometry>
          <material>
            <script>
              <name>Gazebo/Orange</name>
              <uri>file://media/materials/scripts/gazebo.material</uri>
            </script>
          </material>
        </visual>
        <gravity>1</gravity>
        <velocity_decay/>
        <self_collide>0</self_collide>
        <enable_wind>0</enable_wind>
        <kinematic>0</kinematic>
      </link>
      <joint name='leg2_joint' type='revolute'>
        <child>leg2_link</child>
        <parent>thigh2_link</parent>
        <axis>
          <xyz>4e-06 -1 -0</xyz>
          <limit>
            <lower>-2.09</lower>
            <upper>2.09</upper>
            <effort>20</effort>
            <velocity>5</velocity>
          </limit>
          <dynamics>
            <spring_reference>0</spring_reference>
            <spring_stiffness>0</spring_stiffness>
          </dynamics>
          <use_parent_model_frame>1</use_parent_model_frame>
        </axis>
      </joint>
      <link name='hip3_link'>
        <pose frame=''>0.011929 -0.088245 0.10168 1.5708 -0 -2.4981</pose>
        <inertial>
          <pose frame=''>0 0.0175 0.02875 0 -0 0</pose>
          <mass>0.010462</mass>
          <inertia>
            <ixx>1.9878e-06</ixx>
            <ixy>-2.7626e-23</ixy>
            <ixz>-2.3823e-22</ixz>
            <iyy>1.9878e-06</iyy>
            <iyz>-4.8885e-13</iyz>
            <izz>6.7997e-07</izz>
          </inertia>
        </inertial>
        <collision name='hip3_link_collision'>
          <pose frame=''>0 0 0 0 -0 0</pose>
          <geometry>
            <mesh>
              <scale>1 1 1</scale>
              <uri>/home/chhinkein/zeeskee_ws/src/my_spideybot/meshes/hip3_link.STL</uri>
            </mesh>
          </geometry>
          <surface>
            <contact>
              <ode/>
            </contact>
            <friction>
              <ode/>
              <torsional>
                <ode/>
              </torsional>
            </friction>
            <bounce/>
          </surface>
          <max_contacts>10</max_contacts>
        </collision>
        <visual name='hip3_link_visual'>
          <pose frame=''>0 0 0 0 -0 0</pose>
          <geometry>
            <mesh>
              <scale>1 1 1</scale>
              <uri>/home/chhinkein/zeeskee_ws/src/my_spideybot/meshes/hip3_link.STL</uri>
            </mesh>
          </geometry>
          <material>
            <script>
              <name>Gazebo/Blue</name>
              <uri>file://media/materials/scripts/gazebo.material</uri>
            </script>
          </material>
        </visual>
        <gravity>1</gravity>
        <velocity_decay/>
        <self_collide>0</self_collide>
        <enable_wind>0</enable_wind>
        <kinematic>0</kinematic>
      </link>
      <joint name='hip3_joint' type='revolute'>
        <child>hip3_link</child>
        <parent>dummy</parent>
        <axis>
          <xyz>-2e-06 3e-06 1</xyz>
          <limit>
            <lower>-2.09</lower>
            <upper>2.09</upper>
            <effort>20</effort>
            <velocity>5</velocity>
          </limit>
          <dynamics>
            <spring_reference>0</spring_reference>
            <spring_stiffness>0</spring_stiffness>
          </dynamics>
          <use_parent_model_frame>1</use_parent_model_frame>
        </axis>
      </joint>
      <link name='thigh3_link'>
        <pose frame=''>-0.022571 -0.042245 0.11918 -2.35619 -1.57079 1.42889</pose>
        <inertial>
          <pose frame=''>0 -2e-06 0.018733 0 -0 0</pose>
          <mass>0.027144</mass>
          <inertia>
            <ixx>7.8675e-06</ixx>
            <ixy>-1.8488e-17</ixy>
            <ixz>-1.8124e-17</ixz>
            <iyy>6.523e-06</iyy>
            <iyz>-3.5464e-10</iyz>
            <izz>2.8446e-06</izz>
          </inertia>
        </inertial>
        <collision name='thigh3_link_collision'>
          <pose frame=''>0 0 0 0 -0 0</pose>
          <geometry>
            <mesh>
              <scale>1 1 1</scale>
              <uri>/home/chhinkein/zeeskee_ws/src/my_spideybot/meshes/thigh3_link.STL</uri>
            </mesh>
          </geometry>
          <surface>
            <contact>
              <ode/>
            </contact>
            <friction>
              <ode/>
              <torsional>
                <ode/>
              </torsional>
            </friction>
            <bounce/>
          </surface>
          <max_contacts>10</max_contacts>
        </collision>
        <visual name='thigh3_link_visual'>
          <pose frame=''>0 0 0 0 -0 0</pose>
          <geometry>
            <mesh>
              <scale>1 1 1</scale>
              <uri>/home/chhinkein/zeeskee_ws/src/my_spideybot/meshes/thigh3_link.STL</uri>
            </mesh>
          </geometry>
          <material>
            <script>
              <name>Gazebo/Orange</name>
              <uri>file://media/materials/scripts/gazebo.material</uri>
            </script>
          </material>
        </visual>
        <gravity>1</gravity>
        <velocity_decay/>
        <self_collide>0</self_collide>
        <enable_wind>0</enable_wind>
        <kinematic>0</kinematic>
      </link>
      <joint name='thigh3_joint' type='revolute'>
        <child>thigh3_link</child>
        <parent>hip3_link</parent>
        <axis>
          <xyz>0.800005 0.599993 -4e-06</xyz>
          <limit>
            <lower>-2.09</lower>
            <upper>2.09</upper>
            <effort>20</effort>
            <velocity>5</velocity>
          </limit>
          <dynamics>
            <spring_reference>0</spring_reference>
            <spring_stiffness>0</spring_stiffness>
          </dynamics>
          <use_parent_model_frame>1</use_parent_model_frame>
        </axis>
      </joint>
      <link name='leg3_link'>
        <pose frame=''>-0.07057 0.021756 0.119179 3.14159 7e-06 0.643493</pose>
        <inertial>
          <pose frame=''>2.7e-05 0 0.022876 0 -0 0</pose>
          <mass>0.028117</mass>
          <inertia>
            <ixx>2.0146e-05</ixx>
            <ixy>-1.6941e-21</ixy>
            <ixz>-4.0889e-08</ixz>
            <iyy>2.1225e-05</iyy>
            <iyz>-1.35e-21</iyz>
            <izz>2.6051e-06</izz>
          </inertia>
        </inertial>
        <collision name='leg3_link_collision'>
          <pose frame=''>0 0 0 0 -0 0</pose>
          <geometry>
            <mesh>
              <scale>1 1 1</scale>
              <uri>/home/chhinkein/zeeskee_ws/src/my_spideybot/meshes/leg3_link.STL</uri>
            </mesh>
          </geometry>
          <surface>
            <contact>
              <ode/>
            </contact>
            <friction>
              <ode/>
              <torsional>
                <ode/>
              </torsional>
            </friction>
            <bounce/>
          </surface>
          <max_contacts>10</max_contacts>
        </collision>
        <visual name='leg3_link_visual'>
          <pose frame=''>0 0 0 0 -0 0</pose>
          <geometry>
            <mesh>
              <scale>1 1 1</scale>
              <uri>/home/chhinkein/zeeskee_ws/src/my_spideybot/meshes/leg3_link.STL</uri>
            </mesh>
          </geometry>
          <material>
            <script>
              <name>Gazebo/Orange</name>
              <uri>file://media/materials/scripts/gazebo.material</uri>
            </script>
          </material>
        </visual>
        <gravity>1</gravity>
        <velocity_decay/>
        <self_collide>0</self_collide>
        <enable_wind>0</enable_wind>
        <kinematic>0</kinematic>
      </link>
      <joint name='leg3_joint' type='revolute'>
        <child>leg3_link</child>
        <parent>thigh3_link</parent>
        <axis>
          <xyz>0.800005 0.599993 -7e-06</xyz>
          <limit>
            <lower>-2.09</lower>
            <upper>2.09</upper>
            <effort>20</effort>
            <velocity>5</velocity>
          </limit>
          <dynamics>
            <spring_reference>0</spring_reference>
            <spring_stiffness>0</spring_stiffness>
          </dynamics>
          <use_parent_model_frame>1</use_parent_model_frame>
        </axis>
      </joint>
      <link name='hip4_link'>
        <pose frame=''>0.16193 -0.28825 0.10168 1.5708 -0 0.6435</pose>
        <inertial>
          <pose frame=''>0 0.0175 0.02875 0 -0 0</pose>
          <mass>0.010462</mass>
          <inertia>
            <ixx>1.9878e-06</ixx>
            <ixy>9.3745e-24</ixy>
            <ixz>-1.1117e-21</ixz>
            <iyy>1.9878e-06</iyy>
            <iyz>-4.8885e-13</iyz>
            <izz>6.7997e-07</izz>
          </inertia>
        </inertial>
        <collision name='hip4_link_collision'>
          <pose frame=''>0 0 0 0 -0 0</pose>
          <geometry>
            <mesh>
              <scale>1 1 1</scale>
              <uri>/home/chhinkein/zeeskee_ws/src/my_spideybot/meshes/hip4_link.STL</uri>
            </mesh>
          </geometry>
          <surface>
            <contact>
              <ode/>
            </contact>
            <friction>
              <ode/>
              <torsional>
                <ode/>
              </torsional>
            </friction>
            <bounce/>
          </surface>
          <max_contacts>10</max_contacts>
        </collision>
        <visual name='hip4_link_visual'>
          <pose frame=''>0 0 0 0 -0 0</pose>
          <geometry>
            <mesh>
              <scale>1 1 1</scale>
              <uri>/home/chhinkein/zeeskee_ws/src/my_spideybot/meshes/hip4_link.STL</uri>
            </mesh>
          </geometry>
          <material>
            <script>
              <name>Gazebo/Blue</name>
              <uri>file://media/materials/scripts/gazebo.material</uri>
            </script>
          </material>
        </visual>
        <gravity>1</gravity>
        <velocity_decay/>
        <self_collide>0</self_collide>
        <enable_wind>0</enable_wind>
        <kinematic>0</kinematic>
      </link>
      <joint name='hip4_joint' type='revolute'>
        <child>hip4_link</child>
        <parent>dummy</parent>
        <axis>
          <xyz>2e-06 -3e-06 1</xyz>
          <limit>
            <lower>-2.09</lower>
            <upper>2.09</upper>
            <effort>20</effort>
            <velocity>5</velocity>
          </limit>
          <dynamics>
            <spring_reference>0</spring_reference>
            <spring_stiffness>0</spring_stiffness>
          </dynamics>
          <use_parent_model_frame>1</use_parent_model_frame>
        </axis>
      </joint>
      <link name='thigh4_link'>
        <pose frame=''>0.19643 -0.33425 0.11918 -2.35619 -1.57079 -1.71269</pose>
        <inertial>
          <pose frame=''>0 -2e-06 0.018733 0 -0 0</pose>
          <mass>0.027144</mass>
          <inertia>
            <ixx>7.8675e-06</ixx>
            <ixy>-1.8488e-17</ixy>
            <ixz>-1.8123e-17</ixz>
            <iyy>6.523e-06</iyy>
            <iyz>-3.5464e-10</iyz>
            <izz>2.8446e-06</izz>
          </inertia>
        </inertial>
        <collision name='thigh4_link_collision'>
          <pose frame=''>0 0 0 0 -0 0</pose>
          <geometry>
            <mesh>
              <scale>1 1 1</scale>
              <uri>/home/chhinkein/zeeskee_ws/src/my_spideybot/meshes/thigh4_link.STL</uri>
            </mesh>
          </geometry>
          <surface>
            <contact>
              <ode/>
            </contact>
            <friction>
              <ode/>
              <torsional>
                <ode/>
              </torsional>
            </friction>
            <bounce/>
          </surface>
          <max_contacts>10</max_contacts>
        </collision>
        <visual name='thigh4_link_visual'>
          <pose frame=''>0 0 0 0 -0 0</pose>
          <geometry>
            <mesh>
              <scale>1 1 1</scale>
              <uri>/home/chhinkein/zeeskee_ws/src/my_spideybot/meshes/thigh4_link.STL</uri>
            </mesh>
          </geometry>
          <material>
            <script>
              <name>Gazebo/Orange</name>
              <uri>file://media/materials/scripts/gazebo.material</uri>
            </script>
          </material>
        </visual>
        <gravity>1</gravity>
        <velocity_decay/>
        <self_collide>0</self_collide>
        <enable_wind>0</enable_wind>
        <kinematic>0</kinematic>
      </link>
      <joint name='thigh4_joint' type='revolute'>
        <child>thigh4_link</child>
        <parent>hip4_link</parent>
        <axis>
          <xyz>0.800001 0.599999 4e-06</xyz>
          <limit>
            <lower>-2.09</lower>
            <upper>2.09</upper>
            <effort>20</effort>
            <velocity>5</velocity>
          </limit>
          <dynamics>
            <spring_reference>0</spring_reference>
            <spring_stiffness>0</spring_stiffness>
          </dynamics>
          <use_parent_model_frame>1</use_parent_model_frame>
        </axis>
      </joint>
      <link name='leg4_link'>
        <pose frame=''>0.24443 -0.39825 0.119179 -3.14159 -0 0.6435</pose>
        <inertial>
          <pose frame=''>2.7e-05 0 0.022876 0 -0 0</pose>
          <mass>0.028117</mass>
          <inertia>
            <ixx>2.0146e-05</ixx>
            <ixy>1.6941e-21</ixy>
            <ixz>-4.0889e-08</ixz>
            <iyy>2.1225e-05</iyy>
            <iyz>-1.1551e-20</iyz>
            <izz>2.6051e-06</izz>
          </inertia>
        </inertial>
        <collision name='leg4_link_collision'>
          <pose frame=''>0 0 0 0 -0 0</pose>
          <geometry>
            <mesh>
              <scale>1 1 1</scale>
              <uri>/home/chhinkein/zeeskee_ws/src/my_spideybot/meshes/leg4_link.STL</uri>
            </mesh>
          </geometry>
          <surface>
            <contact>
              <ode/>
            </contact>
            <friction>
              <ode/>
              <torsional>
                <ode/>
              </torsional>
            </friction>
            <bounce/>
          </surface>
          <max_contacts>10</max_contacts>
        </collision>
        <visual name='leg4_link_visual'>
          <pose frame=''>0 0 0 0 -0 0</pose>
          <geometry>
            <mesh>
              <scale>1 1 1</scale>
              <uri>/home/chhinkein/zeeskee_ws/src/my_spideybot/meshes/leg4_link.STL</uri>
            </mesh>
          </geometry>
          <material>
            <script>
              <name>Gazebo/Orange</name>
              <uri>file://media/materials/scripts/gazebo.material</uri>
            </script>
          </material>
        </visual>
        <gravity>1</gravity>
        <velocity_decay/>
        <self_collide>0</self_collide>
        <enable_wind>0</enable_wind>
        <kinematic>0</kinematic>
      </link>
      <joint name='leg4_joint' type='revolute'>
        <child>leg4_link</child>
        <parent>thigh4_link</parent>
        <axis>
          <xyz>0.800001 0.599999 -0</xyz>
          <limit>
            <lower>-2.09</lower>
            <upper>2.09</upper>
            <effort>20</effort>
            <velocity>5</velocity>
          </limit>
          <dynamics>
            <spring_reference>0</spring_reference>
            <spring_stiffness>0</spring_stiffness>
          </dynamics>
          <use_parent_model_frame>1</use_parent_model_frame>
        </axis>
      </joint>
      <link name='hip5_link'>
        <pose frame=''>0.19193 -0.18825 0.10168 1.5708 -0 1.5708</pose>
        <inertial>
          <pose frame=''>0 0.0175 0.02875 0 -0 0</pose>
          <mass>0.010462</mass>
          <inertia>
            <ixx>1.9878e-06</ixx>
            <ixy>1.4323e-24</ixy>
            <ixz>-4.9299e-23</ixz>
            <iyy>1.9878e-06</iyy>
            <iyz>-4.8885e-13</iyz>
            <izz>6.7997e-07</izz>
          </inertia>
        </inertial>
        <collision name='hip5_link_collision'>
          <pose frame=''>0 0 0 0 -0 0</pose>
          <geometry>
            <mesh>
              <scale>1 1 1</scale>
              <uri>/home/chhinkein/zeeskee_ws/src/my_spideybot/meshes/hip5_link.STL</uri>
            </mesh>
          </geometry>
          <surface>
            <contact>
              <ode/>
            </contact>
            <friction>
              <ode/>
              <torsional>
                <ode/>
              </torsional>
            </friction>
            <bounce/>
          </surface>
          <max_contacts>10</max_contacts>
        </collision>
        <visual name='hip5_link_visual'>
          <pose frame=''>0 0 0 0 -0 0</pose>
          <geometry>
            <mesh>
              <scale>1 1 1</scale>
              <uri>/home/chhinkein/zeeskee_ws/src/my_spideybot/meshes/hip5_link.STL</uri>
            </mesh>
          </geometry>
          <material>
            <script>
              <name>Gazebo/Blue</name>
              <uri>file://media/materials/scripts/gazebo.material</uri>
            </script>
          </material>
        </visual>
        <gravity>1</gravity>
        <velocity_decay/>
        <self_collide>0</self_collide>
        <enable_wind>0</enable_wind>
        <kinematic>0</kinematic>
      </link>
      <joint name='hip5_joint' type='revolute'>
        <child>hip5_link</child>
        <parent>dummy</parent>
        <axis>
          <xyz>4e-06 0 1</xyz>
          <limit>
            <lower>-2.09</lower>
            <upper>2.09</upper>
            <effort>20</effort>
            <velocity>5</velocity>
          </limit>
          <dynamics>
            <spring_reference>0</spring_reference>
            <spring_stiffness>0</spring_stiffness>
          </dynamics>
          <use_parent_model_frame>1</use_parent_model_frame>
        </axis>
      </joint>
      <link name='thigh5_link'>
        <pose frame=''>0.24943 -0.18825 0.11918 -2.35619 1.57079 -2.35619</pose>
        <inertial>
          <pose frame=''>0 -2e-06 0.018733 0 -0 0</pose>
          <mass>0.027144</mass>
          <inertia>
            <ixx>7.8675e-06</ixx>
            <ixy>-2.1304e-17</ixy>
            <ixz>1.0487e-17</ixz>
            <iyy>6.523e-06</iyy>
            <iyz>-3.5464e-10</iyz>
            <izz>2.8446e-06</izz>
          </inertia>
        </inertial>
        <collision name='thigh5_link_collision'>
          <pose frame=''>0 0 0 0 -0 0</pose>
          <geometry>
            <mesh>
              <scale>1 1 1</scale>
              <uri>/home/chhinkein/zeeskee_ws/src/my_spideybot/meshes/thigh5_link.STL</uri>
            </mesh>
          </geometry>
          <surface>
            <contact>
              <ode/>
            </contact>
            <friction>
              <ode/>
              <torsional>
                <ode/>
              </torsional>
            </friction>
            <bounce/>
          </surface>
          <max_contacts>10</max_contacts>
        </collision>
        <visual name='thigh5_link_visual'>
          <pose frame=''>0 0 0 0 -0 0</pose>
          <geometry>
            <mesh>
              <scale>1 1 1</scale>
              <uri>/home/chhinkein/zeeskee_ws/src/my_spideybot/meshes/thigh5_link.STL</uri>
            </mesh>
          </geometry>
          <material>
            <script>
              <name>Gazebo/Orange</name>
              <uri>file://media/materials/scripts/gazebo.material</uri>
            </script>
          </material>
        </visual>
        <gravity>1</gravity>
        <velocity_decay/>
        <self_collide>0</self_collide>
        <enable_wind>0</enable_wind>
        <kinematic>0</kinematic>
      </link>
      <joint name='thigh5_joint' type='revolute'>
        <child>thigh5_link</child>
        <parent>hip5_link</parent>
        <axis>
          <xyz>4e-06 -1 4e-06</xyz>
          <limit>
            <lower>-2.09</lower>
            <upper>2.09</upper>
            <effort>20</effort>
            <velocity>5</velocity>
          </limit>
          <dynamics>
            <spring_reference>0</spring_reference>
            <spring_stiffness>0</spring_stiffness>
          </dynamics>
          <use_parent_model_frame>1</use_parent_model_frame>
        </axis>
      </joint>
      <link name='leg5_link'>
        <pose frame=''>0.32943 -0.188249 0.119179 3.14159 -7e-06 -1.57079</pose>
        <inertial>
          <pose frame=''>2.7e-05 0 0.022876 0 -0 0</pose>
          <mass>0.028117</mass>
          <inertia>
            <ixx>2.0146e-05</ixx>
            <ixy>1.2116e-22</ixy>
            <ixz>-4.0889e-08</ixz>
            <iyy>2.1225e-05</iyy>
            <iyz>-3.431e-22</iyz>
            <izz>2.6051e-06</izz>
          </inertia>
        </inertial>
        <collision name='leg5_link_collision'>
          <pose frame=''>0 0 0 0 -0 0</pose>
          <geometry>
            <mesh>
              <scale>1 1 1</scale>
              <uri>/home/chhinkein/zeeskee_ws/src/my_spideybot/meshes/leg5_link.STL</uri>
            </mesh>
          </geometry>
          <surface>
            <contact>
              <ode/>
            </contact>
            <friction>
              <ode/>
              <torsional>
                <ode/>
              </torsional>
            </friction>
            <bounce/>
          </surface>
          <max_contacts>10</max_contacts>
        </collision>
        <visual name='leg5_link_visual'>
          <pose frame=''>0 0 0 0 -0 0</pose>
          <geometry>
            <mesh>
              <scale>1 1 1</scale>
              <uri>/home/chhinkein/zeeskee_ws/src/my_spideybot/meshes/leg5_link.STL</uri>
            </mesh>
          </geometry>
          <material>
            <script>
              <name>Gazebo/Orange</name>
              <uri>file://media/materials/scripts/gazebo.material</uri>
            </script>
          </material>
        </visual>
        <gravity>1</gravity>
        <velocity_decay/>
        <self_collide>0</self_collide>
        <enable_wind>0</enable_wind>
        <kinematic>0</kinematic>
      </link>
      <joint name='leg5_joint' type='revolute'>
        <child>leg5_link</child>
        <parent>thigh5_link</parent>
        <axis>
          <xyz>4e-06 -1 7e-06</xyz>
          <limit>
            <lower>-2.09</lower>
            <upper>2.09</upper>
            <effort>20</effort>
            <velocity>5</velocity>
          </limit>
          <dynamics>
            <spring_reference>0</spring_reference>
            <spring_stiffness>0</spring_stiffness>
          </dynamics>
          <use_parent_model_frame>1</use_parent_model_frame>
        </axis>
      </joint>
      <link name='hip6_link'>
        <pose frame=''>0.16193 -0.088245 0.10168 1.5708 -0 2.4981</pose>
        <inertial>
          <pose frame=''>0.086929 -0.18825 0.11918 0 -0 0</pose>
          <mass>0.53458</mass>
          <inertia>
            <ixx>0.0020324</ixx>
            <ixy>5.8234e-19</ixy>
            <ixz>7.2524e-21</ixz>
            <iyy>0.0015098</iyy>
            <iyz>1.2138e-19</iyz>
            <izz>0.0035077</izz>
          </inertia>
        </inertial>
        <collision name='hip6_link_collision'>
          <pose frame=''>0 0 0 0 -0 0</pose>
          <geometry>
            <mesh>
              <scale>1 1 1</scale>
              <uri>/home/chhinkein/zeeskee_ws/src/my_spideybot/meshes/hip6_link.STL</uri>
            </mesh>
          </geometry>
          <surface>
            <contact>
              <ode/>
            </contact>
            <friction>
              <ode/>
              <torsional>
                <ode/>
              </torsional>
            </friction>
            <bounce/>
          </surface>
          <max_contacts>10</max_contacts>
        </collision>
        <visual name='hip6_link_visual'>
          <pose frame=''>0 0 0 0 -0 0</pose>
          <geometry>
            <mesh>
              <scale>1 1 1</scale>
              <uri>/home/chhinkein/zeeskee_ws/src/my_spideybot/meshes/hip6_link.STL</uri>
            </mesh>
          </geometry>
          <material>
            <script>
              <name>Gazebo/Blue</name>
              <uri>file://media/materials/scripts/gazebo.material</uri>
            </script>
          </material>
        </visual>
        <gravity>1</gravity>
        <velocity_decay/>
        <self_collide>0</self_collide>
        <enable_wind>0</enable_wind>
        <kinematic>0</kinematic>
      </link>
      <joint name='hip6_joint' type='revolute'>
        <child>hip6_link</child>
        <parent>dummy</parent>
        <axis>
          <xyz>2e-06 3e-06 1</xyz>
          <limit>
            <lower>-2.09</lower>
            <upper>2.09</upper>
            <effort>20</effort>
            <velocity>5</velocity>
          </limit>
          <dynamics>
            <spring_reference>0</spring_reference>
            <spring_stiffness>0</spring_stiffness>
          </dynamics>
          <use_parent_model_frame>1</use_parent_model_frame>
        </axis>
      </joint>
      <link name='thigh6_link'>
        <pose frame=''>0.19643 -0.042245 0.11918 -2.35619 1.57079 -1.42889</pose>
        <inertial>
          <pose frame=''>0 -2e-06 0.018733 0 -0 0</pose>
          <mass>0.027144</mass>
          <inertia>
            <ixx>7.8675e-06</ixx>
            <ixy>-1.8487e-17</ixy>
            <ixz>-1.8124e-17</ixz>
            <iyy>6.523e-06</iyy>
            <iyz>-3.5464e-10</iyz>
            <izz>2.8446e-06</izz>
          </inertia>
        </inertial>
        <collision name='thigh6_link_collision'>
          <pose frame=''>0 0 0 0 -0 0</pose>
          <geometry>
            <mesh>
              <scale>1 1 1</scale>
              <uri>/home/chhinkein/zeeskee_ws/src/my_spideybot/meshes/thigh6_link.STL</uri>
            </mesh>
          </geometry>
          <surface>
            <contact>
              <ode/>
            </contact>
            <friction>
              <ode/>
              <torsional>
                <ode/>
              </torsional>
            </friction>
            <bounce/>
          </surface>
          <max_contacts>10</max_contacts>
        </collision>
        <visual name='thigh6_link_visual'>
          <pose frame=''>0 0 0 0 -0 0</pose>
          <geometry>
            <mesh>
              <scale>1 1 1</scale>
              <uri>/home/chhinkein/zeeskee_ws/src/my_spideybot/meshes/thigh6_link.STL</uri>
            </mesh>
          </geometry>
          <material>
            <script>
              <name>Gazebo/Orange</name>
              <uri>file://media/materials/scripts/gazebo.material</uri>
            </script>
          </material>
        </visual>
        <gravity>1</gravity>
        <velocity_decay/>
        <self_collide>0</self_collide>
        <enable_wind>0</enable_wind>
        <kinematic>0</kinematic>
      </link>
      <joint name='thigh6_joint' type='revolute'>
        <child>thigh6_link</child>
        <parent>hip6_link</parent>
        <axis>
          <xyz>0.800005 -0.599993 4e-06</xyz>
          <limit>
            <lower>-2.09</lower>
            <upper>2.09</upper>
            <effort>20</effort>
            <velocity>5</velocity>
          </limit>
          <dynamics>
            <spring_reference>0</spring_reference>
            <spring_stiffness>0</spring_stiffness>
          </dynamics>
          <use_parent_model_frame>1</use_parent_model_frame>
        </axis>
      </joint>
      <link name='leg6_link'>
        <pose frame=''>0.244429 0.021756 0.119179 3.14159 -7e-06 -0.643493</pose>
        <inertial>
          <pose frame=''>2.7e-05 0 0.022876 0 -0 0</pose>
          <mass>0.028117</mass>
          <inertia>
            <ixx>2.0146e-05</ixx>
            <ixy>1.6941e-21</ixy>
            <ixz>-4.0889e-08</ixz>
            <iyy>2.1225e-05</iyy>
            <iyz>-6.3682e-21</iyz>
            <izz>2.6051e-06</izz>
          </inertia>
        </inertial>
        <collision name='leg6_link_collision'>
          <pose frame=''>0 0 0 0 -0 0</pose>
          <geometry>
            <mesh>
              <scale>1 1 1</scale>
              <uri>/home/chhinkein/zeeskee_ws/src/my_spideybot/meshes/leg6_link.STL</uri>
            </mesh>
          </geometry>
          <surface>
            <contact>
              <ode/>
            </contact>
            <friction>
              <ode/>
              <torsional>
                <ode/>
              </torsional>
            </friction>
            <bounce/>
          </surface>
          <max_contacts>10</max_contacts>
        </collision>
        <visual name='leg6_link_visual'>
          <pose frame=''>0 0 0 0 -0 0</pose>
          <geometry>
            <mesh>
              <scale>1 1 1</scale>
              <uri>/home/chhinkein/zeeskee_ws/src/my_spideybot/meshes/leg6_link.STL</uri>
            </mesh>
          </geometry>
          <material>
            <script>
              <name>Gazebo/Orange</name>
              <uri>file://media/materials/scripts/gazebo.material</uri>
            </script>
          </material>
        </visual>
        <gravity>1</gravity>
        <velocity_decay/>
        <self_collide>0</self_collide>
        <enable_wind>0</enable_wind>
        <kinematic>0</kinematic>
      </link>
      <joint name='leg6_joint' type='revolute'>
        <child>leg6_link</child>
        <parent>thigh6_link</parent>
        <axis>
          <xyz>0.800005 -0.599993 7e-06</xyz>
          <limit>
            <lower>-2.09</lower>
            <upper>2.09</upper>
            <effort>20</effort>
            <velocity>5</velocity>
          </limit>
          <dynamics>
            <spring_reference>0</spring_reference>
            <spring_stiffness>0</spring_stiffness>
          </dynamics>
          <use_parent_model_frame>1</use_parent_model_frame>
        </axis>
      </joint>
      <static>0</static>
      <plugin name='gazebo_ros_control' filename='libgazebo_ros_control.so'>
        <robotNamespace>/my_spideybot</robotNamespace>
        <robotSimType>gazebo_ros_control/DefaultRobotHWSim</robotSimType>
      </plugin>
      <pose frame=''>0 0 0 0 -0 0</pose>
    </model>
    <model name='simple_arm'>
      <link name='arm_base'>
        <inertial>
          <pose frame=''>0 0 0.00099 0 -0 0</pose>
          <inertia>
            <ixx>1.11</ixx>
            <ixy>0</ixy>
            <ixz>0</ixz>
            <iyy>100.11</iyy>
            <iyz>0</iyz>
            <izz>1.01</izz>
          </inertia>
          <mass>101</mass>
        </inertial>
        <collision name='arm_base_geom'>
          <pose frame=''>0 0 0.05 0 -0 0</pose>
          <geometry>
            <box>
              <size>1 1 0.1</size>
            </box>
          </geometry>
          <max_contacts>10</max_contacts>
          <surface>
            <contact>
              <ode/>
            </contact>
            <bounce/>
            <friction>
              <torsional>
                <ode/>
              </torsional>
              <ode/>
            </friction>
          </surface>
        </collision>
        <visual name='arm_base_geom_visual'>
          <pose frame=''>0 0 0.05 0 -0 0</pose>
          <geometry>
            <box>
              <size>1 1 0.1</size>
            </box>
          </geometry>
          <material>
            <script>
              <uri>file://media/materials/scripts/gazebo.material</uri>
              <name>Gazebo/Blue</name>
            </script>
          </material>
        </visual>
        <collision name='arm_base_geom_arm_trunk'>
          <pose frame=''>0 0 0.6 0 -0 0</pose>
          <geometry>
            <cylinder>
              <radius>0.05</radius>
              <length>1</length>
            </cylinder>
          </geometry>
          <max_contacts>10</max_contacts>
          <surface>
            <contact>
              <ode/>
            </contact>
            <bounce/>
            <friction>
              <torsional>
                <ode/>
              </torsional>
              <ode/>
            </friction>
          </surface>
        </collision>
        <visual name='arm_base_geom_arm_trunk_visual'>
          <pose frame=''>0 0 0.6 0 -0 0</pose>
          <geometry>
            <cylinder>
              <radius>0.05</radius>
              <length>1</length>
            </cylinder>
          </geometry>
          <material>
            <script>
              <uri>file://media/materials/scripts/gazebo.material</uri>
              <name>Gazebo/Red</name>
            </script>
          </material>
        </visual>
        <self_collide>0</self_collide>
        <enable_wind>0</enable_wind>
        <kinematic>0</kinematic>
      </link>
      <link name='arm_shoulder_pan'>
        <pose frame=''>0 0 1.1 0 -0 0</pose>
        <inertial>
          <pose frame=''>0.045455 0 0 0 -0 0</pose>
          <inertia>
            <ixx>0.011</ixx>
            <ixy>0</ixy>
            <ixz>0</ixz>
            <iyy>0.0225</iyy>
            <iyz>0</iyz>
            <izz>0.0135</izz>
          </inertia>
          <mass>1.1</mass>
        </inertial>
        <collision name='arm_shoulder_pan_geom'>
          <pose frame=''>0 0 0.05 0 -0 0</pose>
          <geometry>
            <cylinder>
              <radius>0.05</radius>
              <length>0.1</length>
            </cylinder>
          </geometry>
          <max_contacts>10</max_contacts>
          <surface>
            <contact>
              <ode/>
            </contact>
            <bounce/>
            <friction>
              <torsional>
                <ode/>
              </torsional>
              <ode/>
            </friction>
          </surface>
        </collision>
        <visual name='arm_shoulder_pan_geom_visual'>
          <pose frame=''>0 0 0.05 0 -0 0</pose>
          <geometry>
            <cylinder>
              <radius>0.05</radius>
              <length>0.1</length>
            </cylinder>
          </geometry>
          <material>
            <script>
              <uri>file://media/materials/scripts/gazebo.material</uri>
              <name>Gazebo/Yellow</name>
            </script>
          </material>
        </visual>
        <collision name='arm_shoulder_pan_geom_arm_shoulder'>
          <pose frame=''>0.55 0 0.05 0 -0 0</pose>
          <geometry>
            <box>
              <size>1 0.05 0.1</size>
            </box>
          </geometry>
          <max_contacts>10</max_contacts>
          <surface>
            <contact>
              <ode/>
            </contact>
            <bounce/>
            <friction>
              <torsional>
                <ode/>
              </torsional>
              <ode/>
            </friction>
          </surface>
        </collision>
        <visual name='arm_shoulder_pan_geom_arm_shoulder_visual'>
          <pose frame=''>0.55 0 0.05 0 -0 0</pose>
          <geometry>
            <box>
              <size>1 0.05 0.1</size>
            </box>
          </geometry>
          <material>
            <script>
              <uri>file://media/materials/scripts/gazebo.material</uri>
              <name>Gazebo/Yellow</name>
            </script>
          </material>
        </visual>
        <self_collide>0</self_collide>
        <enable_wind>0</enable_wind>
        <kinematic>0</kinematic>
      </link>
      <link name='arm_elbow_pan'>
        <pose frame=''>1.05 0 1.1 0 -0 0</pose>
        <inertial>
          <pose frame=''>0.0875 0 0.083333 0 -0 0</pose>
          <inertia>
            <ixx>0.031</ixx>
            <ixy>0</ixy>
            <ixz>0.005</ixz>
            <iyy>0.07275</iyy>
            <iyz>0</iyz>
            <izz>0.04475</izz>
          </inertia>
          <mass>1.2</mass>
        </inertial>
        <collision name='arm_elbow_pan_geom'>
          <pose frame=''>0 0 0.1 0 -0 0</pose>
          <geometry>
            <cylinder>
              <radius>0.05</radius>
              <length>0.2</length>
            </cylinder>
          </geometry>
          <max_contacts>10</max_contacts>
          <surface>
            <contact>
              <ode/>
            </contact>
            <bounce/>
            <friction>
              <torsional>
                <ode/>
              </torsional>
              <ode/>
            </friction>
          </surface>
        </collision>
        <visual name='arm_elbow_pan_geom_visual'>
          <pose frame=''>0 0 0.1 0 -0 0</pose>
          <geometry>
            <cylinder>
              <radius>0.05</radius>
              <length>0.2</length>
            </cylinder>
          </geometry>
          <material>
            <script>
              <uri>file://media/materials/scripts/gazebo.material</uri>
              <name>Gazebo/Red</name>
            </script>
          </material>
        </visual>
        <collision name='arm_elbow_pan_geom_arm_elbow'>
          <pose frame=''>0.3 0 0.15 0 -0 0</pose>
          <geometry>
            <box>
              <size>0.5 0.03 0.1</size>
            </box>
          </geometry>
          <max_contacts>10</max_contacts>
          <surface>
            <contact>
              <ode/>
            </contact>
            <bounce/>
            <friction>
              <torsional>
                <ode/>
              </torsional>
              <ode/>
            </friction>
          </surface>
        </collision>
        <visual name='arm_elbow_pan_geom_arm_elbow_visual'>
          <pose frame=''>0.3 0 0.15 0 -0 0</pose>
          <geometry>
            <box>
              <size>0.5 0.03 0.1</size>
            </box>
          </geometry>
          <material>
            <script>
              <uri>file://media/materials/scripts/gazebo.material</uri>
              <name>Gazebo/Yellow</name>
            </script>
          </material>
        </visual>
        <collision name='arm_elbow_pan_geom_arm_wrist'>
          <pose frame=''>0.55 0 0.15 0 -0 0</pose>
          <geometry>
            <cylinder>
              <radius>0.05</radius>
              <length>0.3</length>
            </cylinder>
          </geometry>
          <max_contacts>10</max_contacts>
          <surface>
            <contact>
              <ode/>
            </contact>
            <bounce/>
            <friction>
              <torsional>
                <ode/>
              </torsional>
              <ode/>
            </friction>
          </surface>
        </collision>
        <visual name='arm_elbow_pan_geom_arm_wrist_visual'>
          <pose frame=''>0.55 0 0.15 0 -0 0</pose>
          <geometry>
            <cylinder>
              <radius>0.05</radius>
              <length>0.3</length>
            </cylinder>
          </geometry>
          <material>
            <script>
              <uri>file://media/materials/scripts/gazebo.material</uri>
              <name>Gazebo/Red</name>
            </script>
          </material>
        </visual>
        <self_collide>0</self_collide>
        <enable_wind>0</enable_wind>
        <kinematic>0</kinematic>
      </link>
      <link name='arm_wrist_lift'>
        <pose frame=''>1.6 0 1.05 0 -0 0</pose>
        <inertial>
          <pose frame=''>0 0 0 0 -0 0</pose>
          <inertia>
            <ixx>0.01</ixx>
            <ixy>0</ixy>
            <ixz>0</ixz>
            <iyy>0.01</iyy>
            <iyz>0</iyz>
            <izz>0.001</izz>
          </inertia>
          <mass>0.1</mass>
        </inertial>
        <collision name='arm_wrist_lift_geom'>
          <pose frame=''>0 0 0.5 0 -0 0</pose>
          <geometry>
            <cylinder>
              <radius>0.03</radius>
              <length>1</length>
            </cylinder>
          </geometry>
          <max_contacts>10</max_contacts>
          <surface>
            <contact>
              <ode/>
            </contact>
            <bounce/>
            <friction>
              <torsional>
                <ode/>
              </torsional>
              <ode/>
            </friction>
          </surface>
        </collision>
        <visual name='arm_wrist_lift_geom_visual'>
          <pose frame=''>0 0 0.5 0 -0 0</pose>
          <geometry>
            <cylinder>
              <radius>0.03</radius>
              <length>1</length>
            </cylinder>
          </geometry>
          <material>
            <script>
              <uri>file://media/materials/scripts/gazebo.material</uri>
              <name>Gazebo/Yellow</name>
            </script>
          </material>
        </visual>
        <self_collide>0</self_collide>
        <enable_wind>0</enable_wind>
        <kinematic>0</kinematic>
      </link>
      <link name='arm_wrist_roll'>
        <pose frame=''>1.6 0 1 0 -0 0</pose>
        <inertial>
          <pose frame=''>0 0 0 0 -0 0</pose>
          <inertia>
            <ixx>0.01</ixx>
            <ixy>0</ixy>
            <ixz>0</ixz>
            <iyy>0.01</iyy>
            <iyz>0</iyz>
            <izz>0.001</izz>
          </inertia>
          <mass>0.1</mass>
        </inertial>
        <collision name='arm_wrist_roll_geom'>
          <pose frame=''>0 0 0.025 0 -0 0</pose>
          <geometry>
            <cylinder>
              <radius>0.05</radius>
              <length>0.05</length>
            </cylinder>
          </geometry>
          <max_contacts>10</max_contacts>
          <surface>
            <contact>
              <ode/>
            </contact>
            <bounce/>
            <friction>
              <torsional>
                <ode/>
              </torsional>
              <ode/>
            </friction>
          </surface>
        </collision>
        <visual name='arm_wrist_roll_geom_visual'>
          <pose frame=''>0 0 0.025 0 -0 0</pose>
          <geometry>
            <cylinder>
              <radius>0.05</radius>
              <length>0.05</length>
            </cylinder>
          </geometry>
          <material>
            <script>
              <uri>file://media/materials/scripts/gazebo.material</uri>
              <name>Gazebo/Red</name>
            </script>
          </material>
        </visual>
        <self_collide>0</self_collide>
        <enable_wind>0</enable_wind>
        <kinematic>0</kinematic>
      </link>
      <joint name='arm_shoulder_pan_joint' type='revolute'>
        <parent>arm_base</parent>
        <child>arm_shoulder_pan</child>
        <axis>
          <dynamics>
            <damping>1</damping>
            <friction>0</friction>
            <spring_reference>0</spring_reference>
            <spring_stiffness>0</spring_stiffness>
          </dynamics>
          <xyz>0 0 1</xyz>
          <use_parent_model_frame>1</use_parent_model_frame>
          <limit>
            <lower>-1e+16</lower>
            <upper>1e+16</upper>
          </limit>
        </axis>
      </joint>
      <joint name='arm_elbow_pan_joint' type='revolute'>
        <parent>arm_shoulder_pan</parent>
        <child>arm_elbow_pan</child>
        <axis>
          <dynamics>
            <damping>1</damping>
            <friction>0</friction>
            <spring_reference>0</spring_reference>
            <spring_stiffness>0</spring_stiffness>
          </dynamics>
          <xyz>0 0 1</xyz>
          <use_parent_model_frame>1</use_parent_model_frame>
          <limit>
            <lower>-1e+16</lower>
            <upper>1e+16</upper>
          </limit>
        </axis>
      </joint>
      <joint name='arm_wrist_lift_joint' type='prismatic'>
        <parent>arm_elbow_pan</parent>
        <child>arm_wrist_lift</child>
        <axis>
          <dynamics>
            <damping>1</damping>
            <friction>0</friction>
            <spring_reference>0</spring_reference>
            <spring_stiffness>0</spring_stiffness>
          </dynamics>
          <limit>
            <lower>-0.8</lower>
            <upper>0.1</upper>
          </limit>
          <xyz>0 0 1</xyz>
          <use_parent_model_frame>1</use_parent_model_frame>
        </axis>
      </joint>
      <joint name='arm_wrist_roll_joint' type='revolute'>
        <parent>arm_wrist_lift</parent>
        <child>arm_wrist_roll</child>
        <axis>
          <dynamics>
            <damping>1</damping>
            <friction>0</friction>
            <spring_reference>0</spring_reference>
            <spring_stiffness>0</spring_stiffness>
          </dynamics>
          <limit>
            <lower>-2.99999</lower>
            <upper>2.99999</upper>
          </limit>
          <xyz>0 0 1</xyz>
          <use_parent_model_frame>1</use_parent_model_frame>
        </axis>
      </joint>
      <pose frame=''>0.626666 4.112 0 0 -0 0</pose>
    </model>
    <model name='simple_arm_gripper'>
      <link name='simple_arm::arm_base'>
        <inertial>
          <pose frame=''>0 0 0.00099 0 -0 0</pose>
          <inertia>
            <ixx>1.11</ixx>
            <ixy>0</ixy>
            <ixz>0</ixz>
            <iyy>100.11</iyy>
            <iyz>0</iyz>
            <izz>1.01</izz>
          </inertia>
          <mass>101</mass>
        </inertial>
        <collision name='arm_base_geom'>
          <pose frame=''>0 0 0.05 0 -0 0</pose>
          <geometry>
            <box>
              <size>1 1 0.1</size>
            </box>
          </geometry>
          <max_contacts>10</max_contacts>
          <surface>
            <contact>
              <ode/>
            </contact>
            <bounce/>
            <friction>
              <torsional>
                <ode/>
              </torsional>
              <ode/>
            </friction>
          </surface>
        </collision>
        <visual name='arm_base_geom_visual'>
          <pose frame=''>0 0 0.05 0 -0 0</pose>
          <geometry>
            <box>
              <size>1 1 0.1</size>
            </box>
          </geometry>
          <material>
            <script>
              <uri>file://media/materials/scripts/gazebo.material</uri>
              <name>Gazebo/Blue</name>
            </script>
          </material>
        </visual>
        <collision name='arm_base_geom_arm_trunk'>
          <pose frame=''>0 0 0.6 0 -0 0</pose>
          <geometry>
            <cylinder>
              <radius>0.05</radius>
              <length>1</length>
            </cylinder>
          </geometry>
          <max_contacts>10</max_contacts>
          <surface>
            <contact>
              <ode/>
            </contact>
            <bounce/>
            <friction>
              <torsional>
                <ode/>
              </torsional>
              <ode/>
            </friction>
          </surface>
        </collision>
        <visual name='arm_base_geom_arm_trunk_visual'>
          <pose frame=''>0 0 0.6 0 -0 0</pose>
          <geometry>
            <cylinder>
              <radius>0.05</radius>
              <length>1</length>
            </cylinder>
          </geometry>
          <material>
            <script>
              <uri>file://media/materials/scripts/gazebo.material</uri>
              <name>Gazebo/Red</name>
            </script>
          </material>
        </visual>
        <pose frame=''>0 0 0 0 -0 0</pose>
        <self_collide>0</self_collide>
        <enable_wind>0</enable_wind>
        <kinematic>0</kinematic>
      </link>
      <link name='simple_arm::arm_shoulder_pan'>
        <pose frame=''>0 0 1.1 0 -0 0</pose>
        <inertial>
          <pose frame=''>0.045455 0 0 0 -0 0</pose>
          <inertia>
            <ixx>0.011</ixx>
            <ixy>0</ixy>
            <ixz>0</ixz>
            <iyy>0.0225</iyy>
            <iyz>0</iyz>
            <izz>0.0135</izz>
          </inertia>
          <mass>1.1</mass>
        </inertial>
        <collision name='arm_shoulder_pan_geom'>
          <pose frame=''>0 0 0.05 0 -0 0</pose>
          <geometry>
            <cylinder>
              <radius>0.05</radius>
              <length>0.1</length>
            </cylinder>
          </geometry>
          <max_contacts>10</max_contacts>
          <surface>
            <contact>
              <ode/>
            </contact>
            <bounce/>
            <friction>
              <torsional>
                <ode/>
              </torsional>
              <ode/>
            </friction>
          </surface>
        </collision>
        <visual name='arm_shoulder_pan_geom_visual'>
          <pose frame=''>0 0 0.05 0 -0 0</pose>
          <geometry>
            <cylinder>
              <radius>0.05</radius>
              <length>0.1</length>
            </cylinder>
          </geometry>
          <material>
            <script>
              <uri>file://media/materials/scripts/gazebo.material</uri>
              <name>Gazebo/Yellow</name>
            </script>
          </material>
        </visual>
        <collision name='arm_shoulder_pan_geom_arm_shoulder'>
          <pose frame=''>0.55 0 0.05 0 -0 0</pose>
          <geometry>
            <box>
              <size>1 0.05 0.1</size>
            </box>
          </geometry>
          <max_contacts>10</max_contacts>
          <surface>
            <contact>
              <ode/>
            </contact>
            <bounce/>
            <friction>
              <torsional>
                <ode/>
              </torsional>
              <ode/>
            </friction>
          </surface>
        </collision>
        <visual name='arm_shoulder_pan_geom_arm_shoulder_visual'>
          <pose frame=''>0.55 0 0.05 0 -0 0</pose>
          <geometry>
            <box>
              <size>1 0.05 0.1</size>
            </box>
          </geometry>
          <material>
            <script>
              <uri>file://media/materials/scripts/gazebo.material</uri>
              <name>Gazebo/Yellow</name>
            </script>
          </material>
        </visual>
        <self_collide>0</self_collide>
        <enable_wind>0</enable_wind>
        <kinematic>0</kinematic>
      </link>
      <link name='simple_arm::arm_elbow_pan'>
        <pose frame=''>1.05 0 1.1 0 -0 0</pose>
        <inertial>
          <pose frame=''>0.0875 0 0.083333 0 -0 0</pose>
          <inertia>
            <ixx>0.031</ixx>
            <ixy>0</ixy>
            <ixz>0.005</ixz>
            <iyy>0.07275</iyy>
            <iyz>0</iyz>
            <izz>0.04475</izz>
          </inertia>
          <mass>1.2</mass>
        </inertial>
        <collision name='arm_elbow_pan_geom'>
          <pose frame=''>0 0 0.1 0 -0 0</pose>
          <geometry>
            <cylinder>
              <radius>0.05</radius>
              <length>0.2</length>
            </cylinder>
          </geometry>
          <max_contacts>10</max_contacts>
          <surface>
            <contact>
              <ode/>
            </contact>
            <bounce/>
            <friction>
              <torsional>
                <ode/>
              </torsional>
              <ode/>
            </friction>
          </surface>
        </collision>
        <visual name='arm_elbow_pan_geom_visual'>
          <pose frame=''>0 0 0.1 0 -0 0</pose>
          <geometry>
            <cylinder>
              <radius>0.05</radius>
              <length>0.2</length>
            </cylinder>
          </geometry>
          <material>
            <script>
              <uri>file://media/materials/scripts/gazebo.material</uri>
              <name>Gazebo/Red</name>
            </script>
          </material>
        </visual>
        <collision name='arm_elbow_pan_geom_arm_elbow'>
          <pose frame=''>0.3 0 0.15 0 -0 0</pose>
          <geometry>
            <box>
              <size>0.5 0.03 0.1</size>
            </box>
          </geometry>
          <max_contacts>10</max_contacts>
          <surface>
            <contact>
              <ode/>
            </contact>
            <bounce/>
            <friction>
              <torsional>
                <ode/>
              </torsional>
              <ode/>
            </friction>
          </surface>
        </collision>
        <visual name='arm_elbow_pan_geom_arm_elbow_visual'>
          <pose frame=''>0.3 0 0.15 0 -0 0</pose>
          <geometry>
            <box>
              <size>0.5 0.03 0.1</size>
            </box>
          </geometry>
          <material>
            <script>
              <uri>file://media/materials/scripts/gazebo.material</uri>
              <name>Gazebo/Yellow</name>
            </script>
          </material>
        </visual>
        <collision name='arm_elbow_pan_geom_arm_wrist'>
          <pose frame=''>0.55 0 0.15 0 -0 0</pose>
          <geometry>
            <cylinder>
              <radius>0.05</radius>
              <length>0.3</length>
            </cylinder>
          </geometry>
          <max_contacts>10</max_contacts>
          <surface>
            <contact>
              <ode/>
            </contact>
            <bounce/>
            <friction>
              <torsional>
                <ode/>
              </torsional>
              <ode/>
            </friction>
          </surface>
        </collision>
        <visual name='arm_elbow_pan_geom_arm_wrist_visual'>
          <pose frame=''>0.55 0 0.15 0 -0 0</pose>
          <geometry>
            <cylinder>
              <radius>0.05</radius>
              <length>0.3</length>
            </cylinder>
          </geometry>
          <material>
            <script>
              <uri>file://media/materials/scripts/gazebo.material</uri>
              <name>Gazebo/Red</name>
            </script>
          </material>
        </visual>
        <self_collide>0</self_collide>
        <enable_wind>0</enable_wind>
        <kinematic>0</kinematic>
      </link>
      <link name='simple_arm::arm_wrist_lift'>
        <pose frame=''>1.6 0 1.05 0 -0 0</pose>
        <inertial>
          <pose frame=''>0 0 0 0 -0 0</pose>
          <inertia>
            <ixx>0.01</ixx>
            <ixy>0</ixy>
            <ixz>0</ixz>
            <iyy>0.01</iyy>
            <iyz>0</iyz>
            <izz>0.001</izz>
          </inertia>
          <mass>0.1</mass>
        </inertial>
        <collision name='arm_wrist_lift_geom'>
          <pose frame=''>0 0 0.5 0 -0 0</pose>
          <geometry>
            <cylinder>
              <radius>0.03</radius>
              <length>1</length>
            </cylinder>
          </geometry>
          <max_contacts>10</max_contacts>
          <surface>
            <contact>
              <ode/>
            </contact>
            <bounce/>
            <friction>
              <torsional>
                <ode/>
              </torsional>
              <ode/>
            </friction>
          </surface>
        </collision>
        <visual name='arm_wrist_lift_geom_visual'>
          <pose frame=''>0 0 0.5 0 -0 0</pose>
          <geometry>
            <cylinder>
              <radius>0.03</radius>
              <length>1</length>
            </cylinder>
          </geometry>
          <material>
            <script>
              <uri>file://media/materials/scripts/gazebo.material</uri>
              <name>Gazebo/Yellow</name>
            </script>
          </material>
        </visual>
        <self_collide>0</self_collide>
        <enable_wind>0</enable_wind>
        <kinematic>0</kinematic>
      </link>
      <link name='simple_arm::arm_wrist_roll'>
        <pose frame=''>1.6 0 1 0 -0 0</pose>
        <inertial>
          <pose frame=''>0 0 0 0 -0 0</pose>
          <inertia>
            <ixx>0.01</ixx>
            <ixy>0</ixy>
            <ixz>0</ixz>
            <iyy>0.01</iyy>
            <iyz>0</iyz>
            <izz>0.001</izz>
          </inertia>
          <mass>0.1</mass>
        </inertial>
        <collision name='arm_wrist_roll_geom'>
          <pose frame=''>0 0 0.025 0 -0 0</pose>
          <geometry>
            <cylinder>
              <radius>0.05</radius>
              <length>0.05</length>
            </cylinder>
          </geometry>
          <max_contacts>10</max_contacts>
          <surface>
            <contact>
              <ode/>
            </contact>
            <bounce/>
            <friction>
              <torsional>
                <ode/>
              </torsional>
              <ode/>
            </friction>
          </surface>
        </collision>
        <visual name='arm_wrist_roll_geom_visual'>
          <pose frame=''>0 0 0.025 0 -0 0</pose>
          <geometry>
            <cylinder>
              <radius>0.05</radius>
              <length>0.05</length>
            </cylinder>
          </geometry>
          <material>
            <script>
              <uri>file://media/materials/scripts/gazebo.material</uri>
              <name>Gazebo/Red</name>
            </script>
          </material>
        </visual>
        <self_collide>0</self_collide>
        <enable_wind>0</enable_wind>
        <kinematic>0</kinematic>
      </link>
      <joint name='simple_arm::arm_shoulder_pan_joint' type='revolute'>
        <parent>simple_arm::arm_base</parent>
        <child>simple_arm::arm_shoulder_pan</child>
        <axis>
          <dynamics>
            <damping>1</damping>
            <friction>0</friction>
            <spring_reference>0</spring_reference>
            <spring_stiffness>0</spring_stiffness>
          </dynamics>
          <xyz>0 0 1</xyz>
          <use_parent_model_frame>1</use_parent_model_frame>
          <limit>
            <lower>-1e+16</lower>
            <upper>1e+16</upper>
          </limit>
        </axis>
      </joint>
      <joint name='simple_arm::arm_elbow_pan_joint' type='revolute'>
        <parent>simple_arm::arm_shoulder_pan</parent>
        <child>simple_arm::arm_elbow_pan</child>
        <axis>
          <dynamics>
            <damping>1</damping>
            <friction>0</friction>
            <spring_reference>0</spring_reference>
            <spring_stiffness>0</spring_stiffness>
          </dynamics>
          <xyz>0 0 1</xyz>
          <use_parent_model_frame>1</use_parent_model_frame>
          <limit>
            <lower>-1e+16</lower>
            <upper>1e+16</upper>
          </limit>
        </axis>
      </joint>
      <joint name='simple_arm::arm_wrist_lift_joint' type='prismatic'>
        <parent>simple_arm::arm_elbow_pan</parent>
        <child>simple_arm::arm_wrist_lift</child>
        <axis>
          <dynamics>
            <damping>1</damping>
            <friction>0</friction>
            <spring_reference>0</spring_reference>
            <spring_stiffness>0</spring_stiffness>
          </dynamics>
          <limit>
            <lower>-0.8</lower>
            <upper>0.1</upper>
          </limit>
          <xyz>0 0 1</xyz>
          <use_parent_model_frame>1</use_parent_model_frame>
        </axis>
      </joint>
      <joint name='simple_arm::arm_wrist_roll_joint' type='revolute'>
        <parent>simple_arm::arm_wrist_lift</parent>
        <child>simple_arm::arm_wrist_roll</child>
        <axis>
          <dynamics>
            <damping>1</damping>
            <friction>0</friction>
            <spring_reference>0</spring_reference>
            <spring_stiffness>0</spring_stiffness>
          </dynamics>
          <limit>
            <lower>-2.99999</lower>
            <upper>2.99999</upper>
          </limit>
          <xyz>0 0 1</xyz>
          <use_parent_model_frame>1</use_parent_model_frame>
        </axis>
      </joint>
      <link name='simple_gripper::riser'>
        <pose frame=''>1.65 0 1.5 0 -0 0</pose>
        <inertial>
          <mass>10</mass>
          <inertia>
            <ixx>1</ixx>
            <ixy>0</ixy>
            <ixz>0</ixz>
            <iyy>1</iyy>
            <iyz>0</iyz>
            <izz>1</izz>
          </inertia>
        </inertial>
        <collision name='collision'>
          <geometry>
            <box>
              <size>0.05 0.05 1</size>
            </box>
          </geometry>
          <surface>
            <contact>
              <ode>
                <max_vel>0</max_vel>
              </ode>
            </contact>
            <bounce/>
            <friction>
              <torsional>
                <ode/>
              </torsional>
              <ode/>
            </friction>
          </surface>
          <max_contacts>10</max_contacts>
        </collision>
        <visual name='visual'>
          <geometry>
            <box>
              <size>0.05 0.05 1</size>
            </box>
          </geometry>
        </visual>
        <self_collide>0</self_collide>
        <enable_wind>0</enable_wind>
        <kinematic>0</kinematic>
      </link>
      <link name='simple_gripper::palm'>
        <pose frame=''>1.8 0 1.05 0 -0 0</pose>
        <inertial>
          <mass>0.5</mass>
          <inertia>
            <ixx>1</ixx>
            <ixy>0</ixy>
            <ixz>0</ixz>
            <iyy>1</iyy>
            <iyz>0</iyz>
            <izz>1</izz>
          </inertia>
        </inertial>
        <collision name='collision'>
          <geometry>
            <box>
              <size>0.1 0.2 0.1</size>
            </box>
          </geometry>
          <surface>
            <contact>
              <ode>
                <max_vel>0</max_vel>
              </ode>
            </contact>
            <bounce/>
            <friction>
              <torsional>
                <ode/>
              </torsional>
              <ode/>
            </friction>
          </surface>
          <max_contacts>10</max_contacts>
        </collision>
        <visual name='visual'>
          <geometry>
            <box>
              <size>0.1 0.2 0.1</size>
            </box>
          </geometry>
        </visual>
        <self_collide>0</self_collide>
        <enable_wind>0</enable_wind>
        <kinematic>0</kinematic>
      </link>
      <link name='simple_gripper::left_finger'>
        <pose frame=''>1.9 0.2 1.05 0 0 -0.78539</pose>
        <inertial>
          <mass>0.1</mass>
          <inertia>
            <ixx>1</ixx>
            <ixy>0</ixy>
            <ixz>0</ixz>
            <iyy>1</iyy>
            <iyz>0</iyz>
            <izz>1</izz>
          </inertia>
        </inertial>
        <collision name='collision'>
          <geometry>
            <box>
              <size>0.1 0.3 0.1</size>
            </box>
          </geometry>
          <surface>
            <friction>
              <ode>
                <mu>0.1</mu>
                <mu2>0</mu2>
              </ode>
              <torsional>
                <ode/>
              </torsional>
            </friction>
            <contact>
              <ode>
                <max_vel>0</max_vel>
              </ode>
            </contact>
            <bounce/>
          </surface>
          <max_contacts>10</max_contacts>
        </collision>
        <visual name='visual'>
          <geometry>
            <box>
              <size>0.1 0.3 0.1</size>
            </box>
          </geometry>
        </visual>
        <self_collide>0</self_collide>
        <enable_wind>0</enable_wind>
        <kinematic>0</kinematic>
      </link>
      <link name='simple_gripper::left_finger_tip'>
        <pose frame=''>2.136 0.3 1.05 0 -0 1.5707</pose>
        <inertial>
          <mass>0.5</mass>
          <inertia>
            <ixx>1</ixx>
            <ixy>0</ixy>
            <ixz>0</ixz>
            <iyy>1</iyy>
            <iyz>0</iyz>
            <izz>1</izz>
          </inertia>
        </inertial>
        <collision name='collision'>
          <geometry>
            <box>
              <size>0.1 0.2 0.1</size>
            </box>
          </geometry>
          <surface>
            <friction>
              <ode>
                <mu>0.1</mu>
                <mu2>0</mu2>
              </ode>
              <torsional>
                <ode/>
              </torsional>
            </friction>
            <contact>
              <ode>
                <max_vel>0</max_vel>
              </ode>
            </contact>
            <bounce/>
          </surface>
          <max_contacts>10</max_contacts>
        </collision>
        <visual name='visual'>
          <geometry>
            <box>
              <size>0.1 0.2 0.1</size>
            </box>
          </geometry>
        </visual>
        <self_collide>0</self_collide>
        <enable_wind>0</enable_wind>
        <kinematic>0</kinematic>
      </link>
      <link name='simple_gripper::right_finger'>
        <pose frame=''>1.9 -0.2 1.05 0 -0 0.78539</pose>
        <inertial>
          <mass>0.1</mass>
          <inertia>
            <ixx>1</ixx>
            <ixy>0</ixy>
            <ixz>0</ixz>
            <iyy>1</iyy>
            <iyz>0</iyz>
            <izz>1</izz>
          </inertia>
        </inertial>
        <collision name='collision'>
          <geometry>
            <box>
              <size>0.1 0.3 0.1</size>
            </box>
          </geometry>
          <surface>
            <friction>
              <ode>
                <mu>0.1</mu>
                <mu2>0</mu2>
              </ode>
              <torsional>
                <ode/>
              </torsional>
            </friction>
            <contact>
              <ode>
                <max_vel>0</max_vel>
              </ode>
            </contact>
            <bounce/>
          </surface>
          <max_contacts>10</max_contacts>
        </collision>
        <visual name='visual'>
          <geometry>
            <box>
              <size>0.1 0.3 0.1</size>
            </box>
          </geometry>
        </visual>
        <self_collide>0</self_collide>
        <enable_wind>0</enable_wind>
        <kinematic>0</kinematic>
      </link>
      <link name='simple_gripper::right_finger_tip'>
        <pose frame=''>2.136 -0.3 1.05 0 -0 1.5707</pose>
        <inertial>
          <mass>0.1</mass>
          <inertia>
            <ixx>1</ixx>
            <ixy>0</ixy>
            <ixz>0</ixz>
            <iyy>1</iyy>
            <iyz>0</iyz>
            <izz>1</izz>
          </inertia>
        </inertial>
        <collision name='collision'>
          <geometry>
            <box>
              <size>0.1 0.2 0.1</size>
            </box>
          </geometry>
          <surface>
            <friction>
              <ode>
                <mu>0.1</mu>
                <mu2>0</mu2>
              </ode>
              <torsional>
                <ode/>
              </torsional>
            </friction>
            <contact>
              <ode>
                <max_vel>0</max_vel>
              </ode>
            </contact>
            <bounce/>
          </surface>
          <max_contacts>10</max_contacts>
        </collision>
        <visual name='visual'>
          <geometry>
            <box>
              <size>0.1 0.2 0.1</size>
            </box>
          </geometry>
        </visual>
        <self_collide>0</self_collide>
        <enable_wind>0</enable_wind>
        <kinematic>0</kinematic>
      </link>
      <joint name='simple_gripper::palm_left_finger' type='revolute'>
        <pose frame=''>0 -0.15 0 0 -0 0</pose>
        <child>simple_gripper::left_finger</child>
        <parent>simple_gripper::palm</parent>
        <axis>
          <limit>
            <lower>-0.8</lower>
            <upper>0.8</upper>
          </limit>
          <xyz>0 0 1</xyz>
          <use_parent_model_frame>1</use_parent_model_frame>
          <dynamics>
            <spring_reference>0</spring_reference>
            <spring_stiffness>0</spring_stiffness>
          </dynamics>
        </axis>
      </joint>
      <joint name='simple_gripper::left_finger_tip' type='revolute'>
        <pose frame=''>0 0.1 0 0 -0 0</pose>
        <child>simple_gripper::left_finger_tip</child>
        <parent>simple_gripper::left_finger</parent>
        <axis>
          <limit>
            <lower>-0.8</lower>
            <upper>0.8</upper>
          </limit>
          <xyz>0 0 1</xyz>
          <use_parent_model_frame>1</use_parent_model_frame>
          <dynamics>
            <spring_reference>0</spring_reference>
            <spring_stiffness>0</spring_stiffness>
          </dynamics>
        </axis>
      </joint>
      <joint name='simple_gripper::palm_right_finger' type='revolute'>
        <pose frame=''>0 0.15 0 0 -0 0</pose>
        <child>simple_gripper::right_finger</child>
        <parent>simple_gripper::palm</parent>
        <axis>
          <limit>
            <lower>-0.8</lower>
            <upper>0.8</upper>
          </limit>
          <xyz>0 0 1</xyz>
          <use_parent_model_frame>1</use_parent_model_frame>
          <dynamics>
            <spring_reference>0</spring_reference>
            <spring_stiffness>0</spring_stiffness>
          </dynamics>
        </axis>
      </joint>
      <joint name='simple_gripper::right_finger_tip' type='revolute'>
        <pose frame=''>0 0.1 0 0 -0 0</pose>
        <child>simple_gripper::right_finger_tip</child>
        <parent>simple_gripper::right_finger</parent>
        <axis>
          <limit>
            <lower>-0.8</lower>
            <upper>0.8</upper>
          </limit>
          <xyz>0 0 1</xyz>
          <use_parent_model_frame>1</use_parent_model_frame>
          <dynamics>
            <spring_reference>0</spring_reference>
            <spring_stiffness>0</spring_stiffness>
          </dynamics>
        </axis>
      </joint>
      <joint name='simple_gripper::palm_riser' type='prismatic'>
        <child>simple_gripper::palm</child>
        <parent>simple_gripper::riser</parent>
        <axis>
          <limit>
            <lower>0</lower>
            <upper>0.9</upper>
          </limit>
          <xyz>0 0 1</xyz>
          <use_parent_model_frame>1</use_parent_model_frame>
          <dynamics>
            <spring_reference>0</spring_reference>
            <spring_stiffness>0</spring_stiffness>
          </dynamics>
        </axis>
      </joint>
      <gripper name='simple_gripper'>
        <grasp_check>
          <detach_steps>40</detach_steps>
          <attach_steps>20</attach_steps>
          <min_contact_count>2</min_contact_count>
        </grasp_check>
        <gripper_link>simple_gripper::right_finger</gripper_link>
        <gripper_link>simple_gripper::right_finger_tip</gripper_link>
        <gripper_link>simple_gripper::left_finger</gripper_link>
        <gripper_link>simple_gripper::left_finger_tip</gripper_link>
        <palm_link>simple_gripper::palm</palm_link>
      </gripper>
      <plugin name='simple_arm_plugin' filename='libJointTrajectoryPlugin.so'/>
      <joint name='arm_gripper_joint' type='revolute'>
        <parent>simple_arm::arm_wrist_roll</parent>
        <child>simple_gripper::riser</child>
        <axis>
          <limit>
            <lower>0</lower>
            <upper>0</upper>
          </limit>
          <xyz>0 0 1</xyz>
          <use_parent_model_frame>1</use_parent_model_frame>
          <dynamics>
            <spring_reference>0</spring_reference>
            <spring_stiffness>0</spring_stiffness>
          </dynamics>
        </axis>
      </joint>
      <pose frame=''>1.04994 2.4333 0 0 -0 0</pose>
    </model>
    <model name='unit_box'>
      <pose frame=''>-0.021752 2.10065 0.5 0 -0 0</pose>
      <link name='link'>
        <inertial>
          <mass>1</mass>
          <inertia>
            <ixx>0.166667</ixx>
            <ixy>0</ixy>
            <ixz>0</ixz>
            <iyy>0.166667</iyy>
            <iyz>0</iyz>
            <izz>0.166667</izz>
          </inertia>
        </inertial>
        <collision name='collision'>
          <geometry>
            <box>
              <size>1 1 1</size>
            </box>
          </geometry>
          <max_contacts>10</max_contacts>
          <surface>
            <contact>
              <ode/>
            </contact>
            <bounce/>
            <friction>
              <torsional>
                <ode/>
              </torsional>
              <ode/>
            </friction>
          </surface>
        </collision>
        <visual name='visual'>
          <geometry>
            <box>
              <size>1 1 1</size>
            </box>
          </geometry>
          <material>
            <script>
              <name>Gazebo/Grey</name>
              <uri>file://media/materials/scripts/gazebo.material</uri>
            </script>
          </material>
        </visual>
        <self_collide>0</self_collide>
        <enable_wind>0</enable_wind>
        <kinematic>0</kinematic>
      </link>
    </model>
    <model name='unit_sphere'>
      <pose frame=''>1.94771 1.89411 0.5 0 -0 0</pose>
      <link name='link'>
        <inertial>
          <mass>1</mass>
          <inertia>
            <ixx>0.1</ixx>
            <ixy>0</ixy>
            <ixz>0</ixz>
            <iyy>0.1</iyy>
            <iyz>0</iyz>
            <izz>0.1</izz>
          </inertia>
        </inertial>
        <collision name='collision'>
          <geometry>
            <sphere>
              <radius>0.5</radius>
            </sphere>
          </geometry>
          <max_contacts>10</max_contacts>
          <surface>
            <contact>
              <ode/>
            </contact>
            <bounce/>
            <friction>
              <torsional>
                <ode/>
              </torsional>
              <ode/>
            </friction>
          </surface>
        </collision>
        <visual name='visual'>
          <geometry>
            <sphere>
              <radius>0.5</radius>
            </sphere>
          </geometry>
          <material>
            <script>
              <name>Gazebo/Grey</name>
              <uri>file://media/materials/scripts/gazebo.material</uri>
            </script>
          </material>
        </visual>
        <self_collide>0</self_collide>
        <enable_wind>0</enable_wind>
        <kinematic>0</kinematic>
      </link>
    </model>
    <model name='unit_cylinder'>
      <pose frame=''>0.375946 7.48221 0.5 0 -0 0</pose>
      <link name='link'>
        <inertial>
          <mass>1</mass>
          <inertia>
            <ixx>0.145833</ixx>
            <ixy>0</ixy>
            <ixz>0</ixz>
            <iyy>0.145833</iyy>
            <iyz>0</iyz>
            <izz>0.125</izz>
          </inertia>
        </inertial>
        <collision name='collision'>
          <geometry>
            <cylinder>
              <radius>0.5</radius>
              <length>1</length>
            </cylinder>
          </geometry>
          <max_contacts>10</max_contacts>
          <surface>
            <contact>
              <ode/>
            </contact>
            <bounce/>
            <friction>
              <torsional>
                <ode/>
              </torsional>
              <ode/>
            </friction>
          </surface>
        </collision>
        <visual name='visual'>
          <geometry>
            <cylinder>
              <radius>0.5</radius>
              <length>1</length>
            </cylinder>
          </geometry>
          <material>
            <script>
              <name>Gazebo/Grey</name>
              <uri>file://media/materials/scripts/gazebo.material</uri>
            </script>
          </material>
        </visual>
        <self_collide>0</self_collide>
        <enable_wind>0</enable_wind>
        <kinematic>0</kinematic>
      </link>
    </model>
    <model name='simple_gripper'>
      <link name='riser'>
        <pose frame=''>-0.15 0 0.5 0 -0 0</pose>
        <inertial>
          <mass>10</mass>
          <inertia>
            <ixx>1</ixx>
            <ixy>0</ixy>
            <ixz>0</ixz>
            <iyy>1</iyy>
            <iyz>0</iyz>
            <izz>1</izz>
          </inertia>
        </inertial>
        <collision name='collision'>
          <geometry>
            <box>
              <size>0.05 0.05 1</size>
            </box>
          </geometry>
          <surface>
            <contact>
              <ode>
                <max_vel>0</max_vel>
              </ode>
            </contact>
            <bounce/>
            <friction>
              <torsional>
                <ode/>
              </torsional>
              <ode/>
            </friction>
          </surface>
          <max_contacts>10</max_contacts>
        </collision>
        <visual name='visual'>
          <geometry>
            <box>
              <size>0.05 0.05 1</size>
            </box>
          </geometry>
        </visual>
        <self_collide>0</self_collide>
        <enable_wind>0</enable_wind>
        <kinematic>0</kinematic>
      </link>
      <link name='palm'>
        <pose frame=''>0 0 0.05 0 -0 0</pose>
        <inertial>
          <mass>0.5</mass>
          <inertia>
            <ixx>1</ixx>
            <ixy>0</ixy>
            <ixz>0</ixz>
            <iyy>1</iyy>
            <iyz>0</iyz>
            <izz>1</izz>
          </inertia>
        </inertial>
        <collision name='collision'>
          <geometry>
            <box>
              <size>0.1 0.2 0.1</size>
            </box>
          </geometry>
          <surface>
            <contact>
              <ode>
                <max_vel>0</max_vel>
              </ode>
            </contact>
            <bounce/>
            <friction>
              <torsional>
                <ode/>
              </torsional>
              <ode/>
            </friction>
          </surface>
          <max_contacts>10</max_contacts>
        </collision>
        <visual name='visual'>
          <geometry>
            <box>
              <size>0.1 0.2 0.1</size>
            </box>
          </geometry>
        </visual>
        <self_collide>0</self_collide>
        <enable_wind>0</enable_wind>
        <kinematic>0</kinematic>
      </link>
      <link name='left_finger'>
        <pose frame=''>0.1 0.2 0.05 0 0 -0.78539</pose>
        <inertial>
          <mass>0.1</mass>
          <inertia>
            <ixx>1</ixx>
            <ixy>0</ixy>
            <ixz>0</ixz>
            <iyy>1</iyy>
            <iyz>0</iyz>
            <izz>1</izz>
          </inertia>
        </inertial>
        <collision name='collision'>
          <geometry>
            <box>
              <size>0.1 0.3 0.1</size>
            </box>
          </geometry>
          <surface>
            <friction>
              <ode>
                <mu>0.1</mu>
                <mu2>0</mu2>
              </ode>
              <torsional>
                <ode/>
              </torsional>
            </friction>
            <contact>
              <ode>
                <max_vel>0</max_vel>
              </ode>
            </contact>
            <bounce/>
          </surface>
          <max_contacts>10</max_contacts>
        </collision>
        <visual name='visual'>
          <geometry>
            <box>
              <size>0.1 0.3 0.1</size>
            </box>
          </geometry>
        </visual>
        <self_collide>0</self_collide>
        <enable_wind>0</enable_wind>
        <kinematic>0</kinematic>
      </link>
      <link name='left_finger_tip'>
        <pose frame=''>0.336 0.3 0.05 0 -0 1.5707</pose>
        <inertial>
          <mass>0.5</mass>
          <inertia>
            <ixx>1</ixx>
            <ixy>0</ixy>
            <ixz>0</ixz>
            <iyy>1</iyy>
            <iyz>0</iyz>
            <izz>1</izz>
          </inertia>
        </inertial>
        <collision name='collision'>
          <geometry>
            <box>
              <size>0.1 0.2 0.1</size>
            </box>
          </geometry>
          <surface>
            <friction>
              <ode>
                <mu>0.1</mu>
                <mu2>0</mu2>
              </ode>
              <torsional>
                <ode/>
              </torsional>
            </friction>
            <contact>
              <ode>
                <max_vel>0</max_vel>
              </ode>
            </contact>
            <bounce/>
          </surface>
          <max_contacts>10</max_contacts>
        </collision>
        <visual name='visual'>
          <geometry>
            <box>
              <size>0.1 0.2 0.1</size>
            </box>
          </geometry>
        </visual>
        <self_collide>0</self_collide>
        <enable_wind>0</enable_wind>
        <kinematic>0</kinematic>
      </link>
      <link name='right_finger'>
        <pose frame=''>0.1 -0.2 0.05 0 -0 0.78539</pose>
        <inertial>
          <mass>0.1</mass>
          <inertia>
            <ixx>1</ixx>
            <ixy>0</ixy>
            <ixz>0</ixz>
            <iyy>1</iyy>
            <iyz>0</iyz>
            <izz>1</izz>
          </inertia>
        </inertial>
        <collision name='collision'>
          <geometry>
            <box>
              <size>0.1 0.3 0.1</size>
            </box>
          </geometry>
          <surface>
            <friction>
              <ode>
                <mu>0.1</mu>
                <mu2>0</mu2>
              </ode>
              <torsional>
                <ode/>
              </torsional>
            </friction>
            <contact>
              <ode>
                <max_vel>0</max_vel>
              </ode>
            </contact>
            <bounce/>
          </surface>
          <max_contacts>10</max_contacts>
        </collision>
        <visual name='visual'>
          <geometry>
            <box>
              <size>0.1 0.3 0.1</size>
            </box>
          </geometry>
        </visual>
        <self_collide>0</self_collide>
        <enable_wind>0</enable_wind>
        <kinematic>0</kinematic>
      </link>
      <link name='right_finger_tip'>
        <pose frame=''>0.336 -0.3 0.05 0 -0 1.5707</pose>
        <inertial>
          <mass>0.1</mass>
          <inertia>
            <ixx>1</ixx>
            <ixy>0</ixy>
            <ixz>0</ixz>
            <iyy>1</iyy>
            <iyz>0</iyz>
            <izz>1</izz>
          </inertia>
        </inertial>
        <collision name='collision'>
          <geometry>
            <box>
              <size>0.1 0.2 0.1</size>
            </box>
          </geometry>
          <surface>
            <friction>
              <ode>
                <mu>0.1</mu>
                <mu2>0</mu2>
              </ode>
              <torsional>
                <ode/>
              </torsional>
            </friction>
            <contact>
              <ode>
                <max_vel>0</max_vel>
              </ode>
            </contact>
            <bounce/>
          </surface>
          <max_contacts>10</max_contacts>
        </collision>
        <visual name='visual'>
          <geometry>
            <box>
              <size>0.1 0.2 0.1</size>
            </box>
          </geometry>
        </visual>
        <self_collide>0</self_collide>
        <enable_wind>0</enable_wind>
        <kinematic>0</kinematic>
      </link>
      <joint name='palm_left_finger' type='revolute'>
        <pose frame=''>0 -0.15 0 0 -0 0</pose>
        <child>left_finger</child>
        <parent>palm</parent>
        <axis>
          <limit>
            <lower>-0.8</lower>
            <upper>0.8</upper>
          </limit>
          <xyz>0 0 1</xyz>
          <use_parent_model_frame>1</use_parent_model_frame>
          <dynamics>
            <spring_reference>0</spring_reference>
            <spring_stiffness>0</spring_stiffness>
          </dynamics>
        </axis>
      </joint>
      <joint name='left_finger_tip' type='revolute'>
        <pose frame=''>0 0.1 0 0 -0 0</pose>
        <child>left_finger_tip</child>
        <parent>left_finger</parent>
        <axis>
          <limit>
            <lower>-0.8</lower>
            <upper>0.8</upper>
          </limit>
          <xyz>0 0 1</xyz>
          <use_parent_model_frame>1</use_parent_model_frame>
          <dynamics>
            <spring_reference>0</spring_reference>
            <spring_stiffness>0</spring_stiffness>
          </dynamics>
        </axis>
      </joint>
      <joint name='palm_right_finger' type='revolute'>
        <pose frame=''>0 0.15 0 0 -0 0</pose>
        <child>right_finger</child>
        <parent>palm</parent>
        <axis>
          <limit>
            <lower>-0.8</lower>
            <upper>0.8</upper>
          </limit>
          <xyz>0 0 1</xyz>
          <use_parent_model_frame>1</use_parent_model_frame>
          <dynamics>
            <spring_reference>0</spring_reference>
            <spring_stiffness>0</spring_stiffness>
          </dynamics>
        </axis>
      </joint>
      <joint name='right_finger_tip' type='revolute'>
        <pose frame=''>0 0.1 0 0 -0 0</pose>
        <child>right_finger_tip</child>
        <parent>right_finger</parent>
        <axis>
          <limit>
            <lower>-0.8</lower>
            <upper>0.8</upper>
          </limit>
          <xyz>0 0 1</xyz>
          <use_parent_model_frame>1</use_parent_model_frame>
          <dynamics>
            <spring_reference>0</spring_reference>
            <spring_stiffness>0</spring_stiffness>
          </dynamics>
        </axis>
      </joint>
      <joint name='palm_riser' type='prismatic'>
        <child>palm</child>
        <parent>riser</parent>
        <axis>
          <limit>
            <lower>0</lower>
            <upper>0.9</upper>
          </limit>
          <xyz>0 0 1</xyz>
          <use_parent_model_frame>1</use_parent_model_frame>
          <dynamics>
            <spring_reference>0</spring_reference>
            <spring_stiffness>0</spring_stiffness>
          </dynamics>
        </axis>
      </joint>
      <gripper name='simple_gripper'>
        <grasp_check>
          <detach_steps>40</detach_steps>
          <attach_steps>20</attach_steps>
          <min_contact_count>2</min_contact_count>
        </grasp_check>
        <gripper_link>right_finger</gripper_link>
        <gripper_link>right_finger_tip</gripper_link>
        <gripper_link>left_finger</gripper_link>
        <gripper_link>left_finger_tip</gripper_link>
        <palm_link>palm</palm_link>
      </gripper>
      <pose frame=''>-0.58005 1.43903 0 0 -0 0</pose>
    </model>
    <state world_name='default'>
      <sim_time>103 205000000</sim_time>
      <real_time>279 945034935</real_time>
      <wall_time>1653224969 229860169</wall_time>
      <iterations>103205</iterations>
      <model name='ground_plane'>
        <pose frame=''>0 0 0 0 -0 0</pose>
        <scale>1 1 1</scale>
        <link name='link'>
          <pose frame=''>0 0 0 0 -0 0</pose>
          <velocity>0 0 0 0 -0 0</velocity>
          <acceleration>0 0 0 0 -0 0</acceleration>
          <wrench>0 0 0 0 -0 0</wrench>
        </link>
      </model>
      <model name='my_spideybot'>
        <pose frame=''>0.070239 0.00342 -0.003768 -0.000833 0.000142 -0.077121</pose>
        <scale>1 1 1</scale>
        <link name='dummy'>
          <pose frame=''>0.070239 0.00342 -0.003768 -0.000833 0.000142 -0.077121</pose>
          <velocity>-0.02886 -0.033016 -0.027878 -0.11164 -0.145163 0.259617</velocity>
          <acceleration>-1.53596 -2.8391 2.50559 -0.052255 -0.425298 -0.304062</acceleration>
          <wrench>-0.821093 -1.51773 1.33944 0 -0 0</wrench>
        </link>
        <link name='hip1_link'>
          <pose frame=''>0.05995 -0.28481 0.098152 1.57028 0.000409 -0.721063</pose>
          <velocity>0.030334 -0.024347 0.000558 -0.212092 -0.29324 -0.549004</velocity>
          <acceleration>10.0138 -18.8037 -10.3195 0.271684 1.28357 1.3263</acceleration>
          <wrench>0.104764 -0.196724 -0.107963 0 -0 0</wrench>
        </link>
        <link name='hip2_link'>
          <pose frame=''>0.03774 -0.182792 0.098078 -1.57089 -0.002323 -1.64776</pose>
          <velocity>0.00381 -0.03022 -0.014975 -0.001166 -0.16075 -0.209637</velocity>
          <acceleration>-3.86416 -14.8715 -13.776 1.75518 0.650949 -2.60588</acceleration>
          <wrench>-0.040427 -0.155585 -0.144124 0 -0 0</wrench>
        </link>
        <link name='hip3_link'>
          <pose frame=''>0.075399 -0.085397 0.098043 1.57124 -0.005739 -2.57458</pose>
          <velocity>-0.009333 -0.018943 -0.001392 -0.313575 0.486884 -0.193039</velocity>
          <acceleration>16.444 -14.6137 35.7192 -0.752223 -0.078959 1.13786</acceleration>
          <wrench>0.172037 -0.152889 0.373694 0 -0 0</wrench>
        </link>
        <link name='hip4_link'>
          <pose frame=''>0.209484 -0.296365 0.098153 1.57028 -0.002072 0.566057</pose>
          <velocity>0.034542 0.014362 0.02514 0.01257 -0.254114 -0.428194</velocity>
          <acceleration>12.299 3.90715 11.8197 0.474809 0.715733 2.13125</acceleration>
          <wrench>0.128672 0.040877 0.123658 0 -0 0</wrench>
        </link>
        <link name='hip5_link'>
          <pose frame=''>0.247111 -0.19897 0.098066 1.57066 0.003947 1.49342</pose>
          <velocity>0.008594 0.023498 0.021624 0.603066 -0.172369 -0.582902</velocity>
          <acceleration>-1.83384 -3.53228 15.8135 2.75158 -0.162186 -0.70869</acceleration>
          <wrench>-0.019186 -0.036955 0.165441 0 -0 0</wrench>
        </link>
        <link name='hip6_link'>
          <pose frame=''>0.22491 -0.096954 0.097962 1.57155 0.000389 2.42069</pose>
          <velocity>-0.017505 0.018511 0.005526 -0.11367 -0.145893 0.040966</velocity>
          <acceleration>1.3636 5.41691 -1.90438 -0.373887 -1.4971 -0.074686</acceleration>
          <wrench>0.728955 2.89577 -1.01805 0 -0 0</wrench>
        </link>
        <link name='leg1_link'>
          <pose frame=''>-0.03081 -0.388087 0.115753 3.14055 0.000359 -0.721032</pose>
          <velocity>-0.03188 0.029487 0.010342 -0.242387 -0.255442 -0.551619</velocity>
          <acceleration>-22.1745 0.557715 28.1112 -0.613764 0.591971 -1.18412</acceleration>
          <wrench>-0.623481 0.015681 0.790401 0 -0 0</wrench>
        </link>
        <link name='leg2_link'>
          <pose frame=''>-0.099348 -0.172177 0.115758 3.13998 -0.0022 -1.64778</pose>
          <velocity>0.003297 -0.00137 0.01019 0.007671 0.029516 -0.160428</velocity>
          <acceleration>-20.9774 18.8602 52.8513 1.94096 0.312756 1.86373</acceleration>
          <wrench>-0.589821 0.530293 1.48602 0 -0 0</wrench>
        </link>
        <link name='leg3_link'>
          <pose frame=''>0.001661 0.03066 0.115649 -3.13837 0.005401 0.56689</pose>
          <velocity>0.027377 0.004231 -0.109612 -0.178124 0.425431 -0.165487</velocity>
          <acceleration>38.7075 3.9076 -121.37 -2.97234 -1.21315 0.309882</acceleration>
          <wrench>1.08834 0.10987 -3.41257 0 -0 0</wrench>
        </link>
        <link name='leg4_link'>
          <pose frame=''>0.28318 -0.412434 0.115754 3.14079 -0.0019 0.565999</pose>
          <velocity>-0.019291 -0.017342 -7.2e-05 0.13827 -0.152364 -0.430773</velocity>
          <acceleration>-18.8893 -15.2573 0.010845 2.76268 -1.47098 0.910547</acceleration>
          <wrench>-0.531111 -0.428991 0.000305 0 -0 0</wrench>
        </link>
        <link name='leg5_link'>
          <pose frame=''>0.384203 -0.209526 0.115758 -3.13999 -0.003709 -1.6481</pose>
          <velocity>-0.000553 -0.067766 -0.000345 0.560716 -0.001437 -0.598481</velocity>
          <acceleration>-5.12852 -49.8725 -0.142706 0.845157 1.43805 -0.415329</acceleration>
          <wrench>-0.144199 -1.40226 -0.004012 0 -0 0</wrench>
        </link>
        <link name='leg6_link'>
          <pose frame=''>0.315671 0.006352 0.115768 -3.13759 -0.000457 -0.720888</pose>
          <velocity>-0.024221 0.024006 0.000115 -0.205945 -0.208048 0.046264</velocity>
          <acceleration>-15.5066 10.837 0.229596 1.42306 0.065637 -0.916188</acceleration>
          <wrench>-0.435999 0.304703 0.006456 0 -0 0</wrench>
        </link>
        <link name='thigh1_link'>
          <pose frame=''>0.022004 -0.327998 0.115682 0.364702 -1.56984 0.485039</pose>
          <velocity>0.001167 0.000402 -0.001057 -0.339877 -0.169202 -0.548272</velocity>
          <acceleration>-3.0441 -7.64243 -4.53162 -0.190705 1.29841 -1.61692</acceleration>
          <wrench>-0.082629 -0.207446 -0.123006 0 -0 0</wrench>
        </link>
        <link name='thigh2_link'>
          <pose frame=''>-0.019585 -0.178328 0.115582 -0.79693 -1.56768 0.719976</pose>
          <velocity>0.001958 -0.018269 -0.023815 0.036582 0.424662 -0.211051</velocity>
          <acceleration>-2.54733 1.2704 -0.325256 2.84209 -1.21277 -2.48863</acceleration>
          <wrench>-0.069145 0.034484 -0.008829 0 -0 0</wrench>
        </link>
        <link name='thigh3_link'>
          <pose frame=''>0.044618 -0.036823 0.115511 -1.26704 -1.56508 0.263254</pose>
          <velocity>0.014117 -0.004243 -0.003597 -1.41133 -0.263833 -0.185368</velocity>
          <acceleration>38.145 -2.20132 4.51497 -2.6731 -1.47585 -1.30161</acceleration>
          <wrench>1.03541 -0.059753 0.122554 0 -0 0</wrench>
        </link>
        <link name='thigh4_link'>
          <pose frame=''>0.240279 -0.344912 0.115681 -1.12895 -1.56866 -3.01737</pose>
          <velocity>0.009399 0.000951 0.03249 0.454751 0.042622 -0.426305</velocity>
          <acceleration>-3.10927 -5.90312 9.31465 -1.62371 0.412282 -2.32703</acceleration>
          <wrench>-0.084398 -0.160234 0.252837 0 -0 0</wrench>
        </link>
        <link name='thigh5_link'>
          <pose frame=''>0.304442 -0.203342 0.115571 -1.01232 1.56637 -1.08971</pose>
          <velocity>0.003026 -0.021176 0.028747 0.595186 0.319159 -0.582391</velocity>
          <acceleration>-3.72704 -28.8777 13.4589 -1.9797 -0.925588 -0.764062</acceleration>
          <wrench>-0.101167 -0.783857 0.36533 0 -0 0</wrench>
        </link>
        <link name='thigh6_link'>
          <pose frame=''>0.262867 -0.053745 0.115419 -0.085635 1.56641 0.764244</pose>
          <velocity>-0.021801 0.022041 0.006172 -0.156922 -0.064123 0.042149</velocity>
          <acceleration>-21.4627 14.9582 4.49497 -1.42398 1.24909 1.75969</acceleration>
          <wrench>-0.582583 0.406026 0.122012 0 -0 0</wrench>
        </link>
      </model>
      <model name='simple_arm'>
        <pose frame=''>-2.78313 4.11364 -0 0 0 -0.004412</pose>
        <scale>1 1 1</scale>
        <link name='arm_base'>
          <pose frame=''>-2.78313 4.11364 -0 0 0 -0.004412</pose>
          <velocity>-7e-06 -2e-06 0 0 -0 6e-06</velocity>
          <acceleration>0 0 -0 0 -0 0</acceleration>
          <wrench>0 0 -0 0 -0 0</wrench>
        </link>
        <link name='arm_elbow_pan'>
          <pose frame=''>-1.77358 4.40229 1.1 1e-06 1.1e-05 0.223315</pose>
          <velocity>-3e-06 -1.7e-05 0 -0 -0 -1.8e-05</velocity>
          <acceleration>0 -0 0 0 2e-06 0</acceleration>
          <wrench>0 -0 0 0 -0 0</wrench>
        </link>
        <link name='arm_shoulder_pan'>
          <pose frame=''>-2.78313 4.11364 1.1 1e-06 -3e-06 0.278493</pose>
          <velocity>-7e-06 -2e-06 0 0 0 -1.5e-05</velocity>
          <acceleration>0 -0 -0 0 -0 0</acceleration>
          <wrench>0 -0 -0 0 -0 0</wrench>
        </link>
        <link name='arm_wrist_lift'>
          <pose frame=''>-1.23725 4.52409 0.249989 1e-06 1.5e-05 0.223313</pose>
          <velocity>-1e-06 -2.7e-05 0 0 0 -1.8e-05</velocity>
          <acceleration>0 -0 -0 0 -0 0</acceleration>
          <wrench>0 -0 -0 0 -0 0</wrench>
        </link>
        <link name='arm_wrist_roll'>
          <pose frame=''>-1.23725 4.52409 0.199988 1e-06 1.6e-05 0.233499</pose>
          <velocity>-1e-06 -2.7e-05 0 0 0 -1.8e-05</velocity>
          <acceleration>0 -0 -0 0 -0 0</acceleration>
          <wrench>0 -0 -0 0 -0 0</wrench>
        </link>
      </model>
      <model name='simple_arm_gripper'>
        <pose frame=''>0.914609 3.74954 -0.000151 -0.00031 5e-06 -1.55442</pose>
        <scale>1 1 1</scale>
        <link name='simple_arm::arm_base'>
          <pose frame=''>0.914609 3.74954 -0.000151 -0.00031 5e-06 -1.55442</pose>
          <velocity>-0.00041 -0.000279 -0.039574 -0.000997 0.10023 -0.000419</velocity>
          <acceleration>-0.586873 -0.506445 -0.459266 -2.2832 -0.433351 0.040011</acceleration>
          <wrench>-59.2742 -51.1509 -46.3859 0 -0 0</wrench>
        </link>
        <link name='simple_arm::arm_elbow_pan'>
          <pose frame=''>0.107969 3.07771 1.09995 -8.8e-05 3.9e-05 -1.55522</pose>
          <velocity>0.067995 0.034409 0.013947 -0.00136 0.051101 -0.122809</velocity>
          <acceleration>61.5079 34.3539 13.9958 -0.392646 1.56808 -1.58185</acceleration>
          <wrench>73.8095 41.2246 16.795 0 -0 0</wrench>
        </link>
        <link name='simple_arm::arm_shoulder_pan'>
          <pose frame=''>0.914947 3.74955 1.09984 -0.000167 -0.000274 -2.44727</pose>
          <velocity>0.109505 0.000829 -0.042056 -0.009043 0.107466 -0.033106</velocity>
          <acceleration>108.544 1.98508 -38.0394 -2.17203 0.396445 -1.71086</acceleration>
          <wrench>119.398 2.18359 -41.8433 0 -0 0</wrench>
        </link>
        <link name='simple_arm::arm_wrist_lift'>
          <pose frame=''>0.116517 2.52779 0.80388 -8.2e-05 -9e-06 -1.55521</pose>
          <velocity>-0.01237 0.032524 -0.007305 -0.020991 0.048809 -0.121173</velocity>
          <acceleration>-12.3701 32.5237 -7.30523 -2.1561 -1.45998 -1.80324</acceleration>
          <wrench>-1.23701 3.25237 -0.730524 0 -0 0</wrench>
        </link>
        <link name='simple_arm::arm_wrist_roll'>
          <pose frame=''>0.116514 2.52777 0.75388 -3.4e-05 -7e-06 -1.0691</pose>
          <velocity>-0.014478 0.025174 -0.007287 -0.021561 0.028556 0.025473</velocity>
          <acceleration>-14.4782 25.1736 -7.28702 0.431667 -0.282509 -2.80046</acceleration>
          <wrench>-1.44782 2.51736 -0.728702 0 -0 0</wrench>
        </link>
        <link name='simple_gripper::left_finger'>
          <pose frame=''>0.436161 2.36081 0.804773 4.2e-05 3.2e-05 -1.85475</pose>
          <velocity>5e-06 0.001155 -0.009668 0.001019 0.000428 -0.00021</velocity>
          <acceleration>0.005214 1.15468 -9.6679 1.01875 0.42814 -0.210465</acceleration>
          <wrench>0.000521 0.115468 -0.96679 0 -0 0</wrench>
        </link>
        <link name='simple_gripper::left_finger_tip'>
          <pose frame=''>0.637319 2.20194 0.80478 -6e-06 -5.2e-05 0.501651</pose>
          <velocity>-4.2e-05 0.001321 -0.009948 0.001054 0.000453 -3e-05</velocity>
          <acceleration>-0.041709 1.32113 -9.94811 1.05412 0.45314 -0.029881</acceleration>
          <wrench>-0.020854 0.660567 -4.97405 0 -0 0</wrench>
        </link>
        <link name='simple_gripper::palm'>
          <pose frame=''>0.212724 2.35234 0.804762 5.2e-05 -7e-06 -1.06915</pose>
          <velocity>-7.6e-05 0.001687 -0.009654 0.001025 0.000433 -0.000314</velocity>
          <acceleration>-0.07637 1.68721 -9.65385 1.02465 0.432962 -0.313873</acceleration>
          <wrench>-0.038185 0.843605 -4.82693 0 -0 0</wrench>
        </link>
        <link name='simple_gripper::right_finger'>
          <pose frame=''>0.08548 2.16848 0.804752 3.2e-05 -4.2e-05 -0.283575</pose>
          <velocity>-6.7e-05 0.001588 -0.009767 0.000857 0.000327 1.7e-05</velocity>
          <acceleration>-0.067367 1.58764 -9.76667 0.856975 0.326843 0.017372</acceleration>
          <wrench>-0.006737 0.158764 -0.976667 0 -0 0</wrench>
        </link>
        <link name='simple_gripper::right_finger_tip'>
          <pose frame=''>0.111326 1.91347 0.804749 -8e-06 -5.2e-05 0.501652</pose>
          <velocity>-3.3e-05 0.001351 -0.009956 0.000728 0.000251 -6e-06</velocity>
          <acceleration>-0.032767 1.35089 -9.95559 0.728252 0.250754 -0.006171</acceleration>
          <wrench>-0.003277 0.135089 -0.995559 0 -0 0</wrench>
        </link>
        <link name='simple_gripper::riser'>
          <pose frame=''>0.140571 2.48385 1.25387 5.2e-05 -5e-06 -1.06915</pose>
          <velocity>0.000121 0.001495 -0.00985 0.001522 0.000755 -0.000332</velocity>
          <acceleration>0.121038 1.49498 -9.84996 1.52206 0.755181 -0.332394</acceleration>
          <wrench>1.21038 14.9498 -98.4996 0 -0 0</wrench>
        </link>
      </model>
      <model name='simple_gripper'>
        <pose frame=''>-0.580285 1.44046 -0 0 -0 0.00315</pose>
        <scale>1 1 1</scale>
        <link name='left_finger'>
          <pose frame=''>-0.48014 1.64 0.05 -0 -0 -0.789554</pose>
          <velocity>1.7e-05 1e-05 9.2e-05 -0.000189 0.00029 1.4e-05</velocity>
          <acceleration>0.038882 0.02201 9.76653 -0.376302 0.595415 0.028436</acceleration>
          <wrench>0.003888 0.002201 0.976653 0 -0 0</wrench>
        </link>
        <link name='left_finger_tip'>
          <pose frame=''>-0.243725 1.73944 0.05 0 -0 1.57078</pose>
          <velocity>1.6e-05 9e-06 4.2e-05 -0.000191 0.000289 -1.5e-05</velocity>
          <acceleration>0.035735 0.026825 9.6054 -0.379369 0.596038 0.006516</acceleration>
          <wrench>0.017868 0.013412 4.8027 0 -0 0</wrench>
        </link>
        <link name='palm'>
          <pose frame=''>-0.580285 1.44046 0.05 0 -0 0.00315</pose>
          <velocity>1.3e-05 9e-06 3.9e-05 -0.000191 0.00029 2.3e-05</velocity>
          <acceleration>0.036369 0.017966 9.78714 -0.376657 0.593893 0.023273</acceleration>
          <wrench>0.018185 0.008983 4.89357 0 -0 0</wrench>
        </link>
        <link name='right_finger'>
          <pose frame=''>-0.441237 1.30742 0.05 0 -0 1.30717</pose>
          <velocity>0.009845 0.03638 5.4e-05 -0.0002 0.000292 0.251284</velocity>
          <acceleration>0.028776 -0.011022 9.78303 -0.385663 0.596701 -0.079771</acceleration>
          <wrench>0.002878 -0.001102 0.978302 0 -0 0</wrench>
        </link>
        <link name='right_finger_tip'>
          <pose frame=''>-0.173814 1.28055 0.05 0 -0 1.49102</pose>
          <velocity>0.014216 0.073719 4.4e-05 -0.000205 0.000295 -0.048215</velocity>
          <acceleration>0.016752 -0.027491 9.68204 -0.390235 0.599865 -0.005598</acceleration>
          <wrench>0.001675 -0.002749 0.968204 0 -0 0</wrench>
        </link>
        <link name='riser'>
          <pose frame=''>-0.730284 1.43999 0.5 0 -0 0.00315</pose>
          <velocity>0.000152 9.6e-05 1.5e-05 -0.000191 0.000303 2.4e-05</velocity>
          <acceleration>0.311931 0.189321 9.81182 -0.377513 0.606561 0.024203</acceleration>
          <wrench>3.11931 1.89321 98.1182 0 -0 0</wrench>
        </link>
      </model>
      <model name='unit_box'>
        <pose frame=''>-0.410026 0.961741 0.300747 0.223532 3e-06 -0.012702</pose>
        <scale>0.438558 0.494016 0.504543</scale>
        <link name='link'>
          <pose frame=''>-0.410026 0.961741 0.300747 0.223532 3e-06 -0.012702</pose>
          <velocity>0 0 0 0 -0 0</velocity>
          <acceleration>0 0 -9.8 0 -0 0</acceleration>
          <wrench>0 0 -9.8 0 -0 0</wrench>
        </link>
      </model>
      <model name='unit_cylinder'>
        <pose frame=''>0.375948 7.48221 0.499997 3e-06 4e-06 -0</pose>
        <scale>1 1 1</scale>
        <link name='link'>
          <pose frame=''>0.375948 7.48221 0.499997 3e-06 4e-06 -0</pose>
          <velocity>0 0 0 0 -0 0</velocity>
          <acceleration>0 0 -9.8 0 -0 0</acceleration>
          <wrench>0 0 -9.8 0 -0 0</wrench>
        </link>
      </model>
      <model name='unit_sphere'>
        <pose frame=''>1.94771 1.89411 0.248102 0 -0 0</pose>
        <scale>0.496204 0.496204 0.496204</scale>
        <link name='link'>
          <pose frame=''>1.94771 1.89411 0.248102 0 -0 0</pose>
          <velocity>0 0 0 0 -0 0</velocity>
          <acceleration>0 0 0 0 -0 0</acceleration>
          <wrench>0 0 0 0 -0 0</wrench>
        </link>
      </model>
      <light name='sun'>
        <pose frame=''>0 0 10 0 -0 0</pose>
      </light>
    </state>
    <gui fullscreen='0'>
      <camera name='user_camera'>
        <pose frame=''>5.98924 -3.40618 1.80392 -0 -0.004357 2.13219</pose>
        <view_controller>orbit</view_controller>
        <projection_type>perspective</projection_type>
      </camera>
    </gui>
  </world>
</sdf>
